Workbook

Sheet Master
A1: ID | B1: Flat | C1: Tenant | D1: Owner | E1: Country | F1: Building | G1: Adress | H1: Building | I1: Phone | J1: Parking | K1: Lease Start | L1: Lease end | M1: Rent | N1: EWA account | O1: EWA limit | P1: Internet cost | Q1: Internet Provider | R1: Internet line | S1: Internet line expiry | T1: Hkeeping | U1: HK cost | V1: Maint | W1: Other | X1: CAPEX | Y1: NPV | Z1: Net | AA1: USD | AB1: ROI
A2: 1 | B2: 1307A | C2: Amy | D2: Mohamed | E2: Bahrain | F2: Orchid | G2: FLAT 1307 BUILDING 3331, ROAD 4655, MANAMA / SEA FRONT 0346, CAPITAL GOVERNORATE | H2: 3331 | I2: 3223 1104 | J2: P4-30 | K2: 45748 | L2: 46112 | M2: 350 | N2: 1100253895 | O2: 15 | P2: 6 | Q2: Orchid | S2: 45967 | T2: N/A | U2: 0 | V2: =44*0.5*1.1 -> 24.2 | X2: 40000 | Y2: 53000 | Z2: =M2-O2-P2-U2-V2 -> 304.8 | AA2: =Z2*2.65 -> 807.72 | AB2: =Z2*12/X2 -> 0.09144
A3: 2 | B3: 1407A | D3: Mohamed | E3: Bahrain | F3: Orchid | G3: FLAT 1407 BUILDING 3331, ROAD 4655, MANAMA / SEA FRONT 0346, CAPITAL GOVERNORATE | H3: 3331 | I3: 3335 4746 | J3: P3-39 | K3: 45597 | L3: 45961 | M3: 350 | N3: 1100297355 | O3: 15 | P3: 6 | Q3: Orchid | S3: 45963 | T3: N/A | U3: 0 | V3: =44*0.5*1.1 -> 24.2 | X3: 40000 | Y3: 53000 | Z3: =M3-O3-P3-U3-V3 -> 304.8 | AA3: =Z3*2.65 -> 807.72 | AB3: =Z3*12/X3 -> 0.09144
A4: 3 | B4: 1306B | C4: Zahraa | D4: Ayyoub | E4: Bahrain | F4: Orchid | G4: FLAT 1306 BUILDING 3329, ROAD 4655, MANAMA / SEA FRONT 0346, CAPITAL GOVERNORATE | H4: 3329 | I4: 6666 8989 | J4: P6-19 | K4: 45210 | L4: 46305 | M4: 500 | N4: 1100318912 | O4: 20 | P4: 6 | Q4: Orchid | S4: 46021 | T4: N/A | U4: 0 | V4: =68*0.8*1.1 -> 59.84 | X4: 70000 | Y4: 75000 | Z4: =M4-O4-P4-U4-V4 -> 414.16 | AA4: =Z4*2.65 -> 1097.524 | AB4: =Z4*12/X4 -> 0.070998857
A5: 4 | B5: 1509B | C5: Sultan | D5: Mohamed | E5: Bahrain | F5: Orchid | G5: FLAT 1509 BUILDING 3329, ROAD 4655, MANAMA / SEA FRONT 0346, CAPITAL GOVERNORATE | H5: 3329 | I5: 560490705 | J5: P6-48 | K5: 45532 | L5: 45896 | M5: 350 | N5: 1100119864 | O5: 15 | P5: 6 | Q5: Orchid | S5: 45964 | T5: N/A | U5: 0 | V5: =44*0.5*1.1 -> 24.2 | X5: 37500 | Y5: 50000 | Z5: =M5-O5-P5-U5-V5 -> 304.8 | AA5: =Z5*2.65 -> 807.72 | AB5: =Z5*12/X5 -> 0.097536
A6: 5 | B6: 2206B | C6: Abdulaziz | D6: Rami | E6: Bahrain | F6: Orchid | G6: FLAT 2206 BUILDING 3329, ROAD 4655, MANAMA / SEA FRONT 0346, CAPITAL GOVERNORATE | H6: 3329 | I6: 552427972 | J6: P3-41 | K6: 45918 | L6: 46282 | M6: 540 | N6: 1100331105 | O6: 25 | P6: 16.18 | Q6: Batelco | R6: 17406284 | S6: 45776 | T6: N/A | U6: 0 | V6: =68*0.8*1.1 -> 59.84 | W6: =5%*M6 -> 27 | X6: 73000 | Y6: 78000 | Z6: =M6-O6-P6-U6-V6 -> 438.98 | AA6: =Z6*2.65 -> 1163.297 | AB6: =Z6*12/X6 -> 0.072161096
A7: 6 | B7: 2306B | C7: Loai | D7: Mohamed | E7: Bahrain | F7: Orchid | G7: FLAT 2306 BUILDING 3329, ROAD 4655, MANAMA / SEA FRONT 0346, CAPITAL GOVERNORATE | H7: 3329 | I7: 6694 4446 | J7: P3-40 | K7: 45017 | L7: 46112 | M7: 480 | N7: 1100297470 | O7: 30 | P7: 0 | T7: N/A | U7: 0 | V7: =68*0.5*1.1 -> 37.4 | X7: 73000 | Y7: 78000 | Z7: =M7-O7-P7-U7-V7 -> 412.6 | AA7: =Z7*2.65 -> 1093.39 | AB7: =Z7*12/X7 -> 0.067824658
A8: 7 | B8: 2706B | C8: Mike | D8: Mohamed | E8: Bahrain | F8: Orchid | G8: FLAT 2706 BUILDING 3329, ROAD 4655, MANAMA / SEA FRONT 0346, CAPITAL GOVERNORATE | H8: 3329 | I8: 3944 4700 | J8: P2-30 | K8: 45862 | L8: 46226 | M8: 560 | N8: 1100290012 | O8: 20 | P8: 6 | Q8: Orchid | S8: 46117 | T8: N/A | U8: 0 | V8: =68*0.5*1.1 -> 37.4 | X8: 75000 | Y8: 79000 | Z8: =M8-O8-P8-U8-V8 -> 496.6 | AA8: =Z8*2.65 -> 1315.99 | AB8: =Z8*12/X8 -> 0.079456
A9: 8 | B9: 1206 | C9: Amal | D9: Mohamed | E9: Bahrain | F9: Catamaran | G9: FLAT 1206 BUILDING 3132, ROAD 4653, MANAMA / SEA FRONT 0346, CAPITAL GOVERNORATE | H9: 3332 | I9: 3665 2052 | J9: P3-559 | K9: 44866 | L9: 46326 | M9: 500 | N9: 1041898808 | O9: 20 | P9: 16.18 | Q9: Batelco | R9: 17490076 | S9: 46498 | T9: 2/wek+linen | U9: 33 | V9: =68*0.8*1.1 -> 59.84 | X9: 65000 | Y9: 75000 | Z9: =M9-O9-P9-U9-V9 -> 370.98 | AA9: =Z9*2.65 -> 983.097 | AB9: =Z9*12/X9 -> 0.068488615
A10: 9 | B10: 1306 | C10: Fatme Ali Hamdan | D10: Mondir | E10: Bahrain | F10: Catamaran | G10: FLAT 1306 BUILDING 3132, ROAD 4653, MANAMA / SEA FRONT 0346, CAPITAL GOVERNORATE | H10: 3332 | I10: 3443 8384 | J10: P2-350 | K10: 45413 | L10: 46142 | M10: 500 | N10: 1100872009 | O10: 25 | P10: 14.5 | Q10: Catamaran | R10: 17540587 | T10: 1/wek+linen | U10: 19.8 | V10: =68*0.8*1.1 -> 59.84 | X10: 76000 | Y10: 77000 | Z10: =M10-O10-P10-U10-V10 -> 380.86 | AA10: =Z10*2.65 -> 1009.279 | AB10: =Z10*12/X10 -> 0.060135789
A11: 10 | B11: 1405 | C11: Peter Alan | D11: Mohamed | E11: Bahrain | F11: Catamaran | G11: FLAT 1405 BUILDING 3132, ROAD 4653, MANAMA / SEA FRONT 0346, CAPITAL GOVERNORATE | H11: 3332 | I11: 509666527 | J11: P3-498 | K11: 45566 | L11: 46295 | M11: 525 | N11: 1101561510 | O11: 25 | P11: 14.5 | Q11: Catamaran | R11: 17262893 | T11: 2/wek+linen | U11: 33 | V11: =68*0.8*1.1 -> 59.84 | X11: 75000 | Y11: 75000 | Z11: =M11-O11-P11-U11-V11 -> 392.66 | AA11: =Z11*2.65 -> 1040.549 | AB11: =Z11*12/X11 -> 0.0628256
A12: 11 | B12: 1805 | C12: Islam | D12: Mohamed | E12: Bahrain | F12: Catamaran | G12: FLAT 1805 BUILDING 3132, ROAD 4653, MANAMA / SEA FRONT 0346, CAPITAL GOVERNORATE | H12: 3332 | I12: 3990 5099 | J12: P2-329 | K12: 45797 | L12: 46161 | M12: 500 | N12: 1101077285 | O12: 20 | P12: 16.18 | Q12: Batelco | R12: 17040571 | S12: 46121 | T12: 1/wek+linen | U12: 19.8 | V12: =68*0.8*1.1 -> 59.84 | X12: 65000 | Y12: 76000 | Z12: =M12-O12-P12-U12-V12 -> 384.18 | AA12: =Z12*2.65 -> 1018.077 | AB12: =Z12*12/X12 -> 0.070925538
A13: 12 | B13: 2105 | C13: Mikhail | D13: Mohamed | E13: Bahrain | F13: Catamaran | G13: FLAT 2105 BUILDING 3132, ROAD 4653, MANAMA / SEA FRONT 0346, CAPITAL GOVERNORATE | H13: 3332 | I13: 3366 3419 | J13: P1-65 | K13: 45677 | L13: 46041 | M13: 550 | N13: 1061665988 | O13: 25 | P13: 16.18 | Q13: Batelco | R13: 17431291 | S13: 45827 | T13: 1/wek+linen | U13: 19.8 | V13: =68*0.8*1.1 -> 59.84 | X13: 65000 | Y13: 78000 | Z13: =M13-O13-P13-U13-V13 -> 429.18 | AA13: =Z13*2.65 -> 1137.327 | AB13: =Z13*12/X13 -> 0.079233231
A14: 13 | B14: 2106 | C14: Ibrahim | D14: Rami | E14: Bahrain | F14: Catamaran | G14: FLAT 2106 BUILDING 3132, ROAD 4653, MANAMA / SEA FRONT 0346, CAPITAL GOVERNORATE | H14: 3332 | I14: 509988877 | J14: P1-66 | K14: 44504 | L14: 46329 | M14: 500 | N14: 1062477474 | O14: 25 | P14: 16.18 | Q14: Batelco | R14: 17825907 | S14: 45778 | T14: 2/wek+linen | U14: 33 | V14: =68*0.8*1.1 -> 59.84 | W14: =5%*M14 -> 25 | X14: 65000 | Y14: 78000 | Z14: =M14-O14-P14-U14-V14 -> 365.98 | AA14: =Z14*2.65 -> 969.847 | AB14: =Z14*12/X14 -> 0.067565538
A15: 14 | B15: 3507 | C15: Mohamed | D15: Rami | E15: Bahrain | F15: Catamaran | G15: FLAT 3507 BUILDING 3132, ROAD 4653, MANAMA / SEA FRONT 0346, CAPITAL GOVERNORATE | H15: 3332 | I15: 39684499 | J15: P1-212 | K15: 45566 | L15: 45930 | M15: 1100 | N15: 1101758876 | O15: 50 | P15: 16.18 | Q15: Batelco | T15: 2/wek+linen | U15: 55 | V15: =151*0.8*1.1 -> 132.88 | W15: =5%*M15 -> 55 | X15: 175000 | Y15: 175000 | Z15: =M15-O15-P15-U15-V15 -> 845.94 | AA15: =Z15*2.65 -> 2241.741 | AB15: =Z15*12/X15 -> 0.058007314
A16: 15 | B16: 1706 | C16: Paul | D16: Omar | E16: Bahrain | F16: Catamaran | G16: FLAT 1706 BUILDING 3132, ROAD 4653, MANAMA / SEA FRONT 0346, CAPITAL GOVERNORATE | H16: 3332 | I16: 500878748 | J16: P2-385 | K16: 45512 | L16: 46241 | M16: 575 | N16: 1101799219 | O16: 25 | P16: 14.5 | Q16: Catamaran | R16: 17273240 | T16: 1/wek+linen | U16: 19.8 | V16: =66.8*0.8*1.1 -> 58.784 | W16: =5%*M16 -> 28.75 | X16: =74000*1.03 -> 76220 | Y16: 78000 | Z16: =M16-O16-P16-U16-V16 -> 456.916 | AA16: =Z16*2.65 -> 1210.8274 | AB16: =Z16*12/X16 -> 0.071936395
A17: 16 | B17: 2305 | C17: Said | D17: Mohamed | E17: Bahrain | F17: Catamaran | G17: FLAT 2305 BUILDING 3132, ROAD 4653, MANAMA / SEA FRONT 0346, CAPITAL GOVERNORATE | H17: 3332 | I17: 66675044 | J17: P2-xxxx | K17: 45884 | L17: 46248 | M17: 515 | N17: 1102106455 | O17: 25 | P17: 0 | Q17: N/A | R17: N/A | S17: N/A | T17: N/A | U17: 0 | V17: =68*0.8*1.1 -> 59.84 | X17: 67000 | Y17: 78000 | Z17: =M17-O17-P17-U17-V17 -> 430.16 | AA17: =Z17*2.65 -> 1139.924 | AB17: =Z17*12/X17 -> 0.077043582
A18: 17 | B18: 3504 | D18: Mohamed | E18: Bahrain | F18: Catamaran | G18: FLAT 3504 BUILDING 3132, ROAD 4653, MANAMA / SEA FRONT 0346, CAPITAL GOVERNORATE | H18: 3332 | J18: P1-90 | N18: 1100362969 | Q18: Batelco | R18: 17043806 | S18: 46324 | T18: N/A | U18: 0 | V18: =68*0.8*1.1 -> 59.84 | X18: 108000 | Y18: 125000 | Z18: =M18-O18-P18-U18-V18 -> -59.84 | AA18: =Z18*2.65 -> -158.576 | AB18: =Z18*12/X18 -> -0.0066488889
A19: 17 | B19: Pierrefitte | C19: Afgan | D19: Mohamed | E19: France | F19: Tour M3 | T19: N/A | X19: =125000*0.4 -> 50000 | Y19: 54000 | Z19: 300 | AA19: =Z19*2.65 -> 795 | AB19: =Z19*12/X19 -> 0.072
A20: 18 | B20: Aubepine | C20: Polonais | D20: Mohamed | E20: France | F20: Aubepine | T20: N/A | X20: =175000*0.4 -> 70000 | Y20: 80000 | Z20: 300 | AA20: =Z20*2.65 -> 795 | AB20: =Z20*12/X20 -> 0.051428571
A21: 19 | B21: Figuiers | C21: Briote | D21: Mohamed | E21: France | F21: Figuiers | T21: N/A | X21: =175000*0.4 -> 70000 | Y21: 80000 | Z21: 300 | AA21: =Z21*2.65 -> 795 | AB21: =Z21*12/X21 -> 0.051428571
X22: =SUBTOTAL(9,X2:X21) -> 1435720 | Y22: =SUBTOTAL(9,Y2:Y21) -> 1595000 | Z22: =SUBTOTAL(9,Z2:Z21) -> 7573.756 | AA22: =SUBTOTAL(9,AA2:AA21) -> 20070.453

Sheet 1307A
A1: Flat | B1: =Master!B2 -> 1307A | C1: Parking | D1: =Master!J2 -> P4-30 | E1: EWA | F1: =Master!N2 -> 1100253895 | G1: EWA limit | H1: =Master!O2 -> 15
A2: Tenant | B2: =Master!C2 -> Amy | C2: Phone | D2: =Master!I2 -> 3223 1104 | E2: Lease Start | F2: =Master!K2 -> 45748 | G2: Lease end | H2: =Master!L2 -> 46112
A3: Month | B3: Rent | C3: EWA | D3: Chiller | E3: Internet | F3: Housekeeping | G3: Manage. fees | H3: Other fees | I3: Comments | J3: EWA Excess | K3: Excess pay
A4: Balance: | B4: 0 | C4: Balance Date: | D4: 45291
A5: 45292 | B5: 370 | C5: 10.63 | E5: 14.5 | J5: =IF((C5+D5)>$H$1,(C5+D5)-$H$1,0) -> 0
A6: 45323 | B6: 370 | C6: 9.3 | E6: 14.5 | H6: 231.55 | I6: Annual maintenance | J6: =IF((C6+D6)>$H$1,(C6+D6)-$H$1,0) -> 0
A7: 45352 | B7: 370 | C7: 11.15 | E7: 14.5 | J7: =IF((C7+D7)>$H$1,(C7+D7)-$H$1,0) -> 0
A8: 45383 | B8: 370 | C8: 11.09 | E8: 14.5 | J8: =IF((C8+D8)>$H$1,(C8+D8)-$H$1,0) -> 0
A9: 45413 | B9: 370 | C9: 12.37 | E9: 14.5 | J9: =IF((C9+D9)>$H$1,(C9+D9)-$H$1,0) -> 0
A10: 45444 | B10: 370 | C10: 16.66 | E10: 14.5 | J10: =IF((C10+D10)>$H$1,(C10+D10)-$H$1,0) -> 1.66 | K10: Paid
A11: 45474 | B11: 370 | C11: 8.35 | E11: 14.5 | J11: =IF((C11+D11)>$H$1,(C11+D11)-$H$1,0) -> 0
A12: 45505 | B12: 370 | C12: 8.61 | E12: 14.5 | J12: =IF((C12+D12)>$H$1,(C12+D12)-$H$1,0) -> 0
A13: 45536 | B13: 370 | C13: 15.87 | E13: 14.5 | J13: =IF((C13+D13)>$H$1,(C13+D13)-$H$1,0) -> 0.87 | K13: Paid
A14: 45566 | B14: 370 | C14: 8.19 | E14: 14.5 | J14: =IF((C14+D14)>$H$1,(C14+D14)-$H$1,0) -> 0
A15: 45597 | B15: 370 | C15: 18.84 | E15: 14.5 | H15: 370 | I15: Security deposit refund | J15: =IF((C15+D15)>$H$1,(C15+D15)-$H$1,0) -> 3.84 | K15: Paid
A16: 45627 | B16: 0 | C16: 9.61 | E16: 6 | J16: =IF((C16+D16)>$H$1,(C16+D16)-$H$1,0) -> 0 | L16: =SUM(B5:B16)-SUM(C5:C16)-SUM(D5:D16)-SUM(E5:E16)-SUM(F5:F16)-SUM(G5:G16)-SUM(H5:H16)+SUM(J5:J16) -> 3168.65
A17: 45658 | B17: 700 | C17: 9.16 | E17: 6 | H17: 350 | I17: Agent fees | J17: =IF(C17>$H$1,C17-$H$1,0) -> 0
A18: 45689 | B18: 350 | C18: 16.66 | E18: 6 | H18: 231.55 | I18: Annual maintenance | J18: =IF(C18>$H$1,C18-$H$1,0) -> 1.66
A19: 45717 | B19: 350 | C19: 17.3 | E19: 6 | I19: Tenant runaway | J19: =IF(C19>$H$1,C19-$H$1,0) -> 2.3
A20: 45748 | B20: 350 | C20: 7.97 | E20: 6 | J20: =IF(C20>$H$1,C20-$H$1,0) -> 0
A21: 45778 | B21: 350 | C21: 11.35 | E21: 6 | J21: =IF(C21>$H$1,C21-$H$1,0) -> 0
A22: 45809 | B22: 350 | C22: 13.76 | E22: 6 | J22: =IF(C22>$H$1,C22-$H$1,0) -> 0
A23: 45839 | B23: 350 | C23: 13.62 | E23: 6 | J23: =IF(C23>$H$1,C23-$H$1,0) -> 0
A24: 45870 | B24: 350 | C24: 15.73 | E24: 6 | J24: =IF(C24>$H$1,C24-$H$1,0) -> 0.73
A25: 45901 | B25: 350 | C25: 13.91 | E25: 6 | J25: =IF(C25>$H$1,C25-$H$1,0) -> 0
A26: 45931 | B26: 350 | C26: 12.95 | E26: 6 | J26: =IF(C26>$H$1,C26-$H$1,0) -> 0
A27: 45962 | B27: 350 | C27: 12.16 | E27: 6 | J27: =IF(C27>$H$1,C27-$H$1,0) -> 0
A28: 45992 | B28: 350 | C28: 11.87 | E28: 6 | J28: =IF(C28>$H$1,C28-$H$1,0) -> 0 | L28: =SUM(B17:B28)-SUM(C17:C28)-SUM(D17:D28)-SUM(E17:E28)-SUM(F17:F28)-SUM(G17:G28)-SUM(H17:H28)+SUM(J17:J28) -> 3744.7
A29: 46023 | B29: 350 | E29: 6 | J29: =IF(C29>$H$1,C29-$H$1,0) -> 0
A30: 46054 | J30: =IF(C30>$H$1,C30-$H$1,0) -> 0
A31: 46082 | J31: =IF(C31>$H$1,C31-$H$1,0) -> 0
A32: 46113 | J32: =IF(C32>$H$1,C32-$H$1,0) -> 0
A33: 46143 | J33: =IF(C33>$H$1,C33-$H$1,0) -> 0
A34: 46174 | J34: =IF(C34>$H$1,C34-$H$1,0) -> 0
A35: 46204 | J35: =IF(C35>$H$1,C35-$H$1,0) -> 0
A36: 46235 | J36: =IF(C36>$H$1,C36-$H$1,0) -> 0
A37: 46266 | J37: =IF(C37>$H$1,C37-$H$1,0) -> 0
A38: 46296 | J38: =IF(C38>$H$1,C38-$H$1,0) -> 0
A39: 46327 | J39: =IF(C39>$H$1,C39-$H$1,0) -> 0
A40: 46357 | J40: =IF(C40>$H$1,C40-$H$1,0) -> 0 | L40: =SUM(B29:B40)-SUM(C29:C40)-SUM(D29:D40)-SUM(E29:E40)-SUM(F29:F40)-SUM(G29:G40)-SUM(H29:H40)+SUM(J29:J40) -> 344
...

Sheet 1407A
A1: Flat | B1: =Master!B3 -> 1407A | C1: Parking | D1: =Master!J3 -> P3-39 | E1: EWA | F1: =Master!N3 -> 1100297355 | G1: EWA limit | H1: =Master!O3 -> 15
A2: Tenant | B2: =Master!C3 -> 0 | C2: Phone | D2: =Master!I3 -> 3335 4746 | E2: Lease Start | F2: =Master!K3 -> 45597 | G2: Lease end | H2: =Master!L3 -> 45961
A3: Month | B3: Rent | C3: EWA | D3: Chiller | E3: Internet | F3: Housekeeping | G3: Manage. fees | H3: Other fees | I3: Comments | J3: EWA Excess | K3: Excess pay
A4: Balance: | B4: 0 | C4: Balance Date: | D4: 45291
A5: 45292 | B5: 350 | C5: 17.29 | E5: 6 | J5: =IF((C5+D5)>$H$1,(C5+D5)-$H$1,0) -> 2.29 | K5: Paid
A6: 45323 | B6: 350 | C6: 15.61 | E6: 6 | J6: =IF((C6+D6)>$H$1,(C6+D6)-$H$1,0) -> 0.61 | K6: Paid
A7: 45352 | B7: 350 | C7: 16.62 | E7: 6 | J7: =IF((C7+D7)>$H$1,(C7+D7)-$H$1,0) -> 1.62 | K7: Paid
A8: 45383 | B8: 350 | C8: 11.21 | E8: 6 | J8: =IF((C8+D8)>$H$1,(C8+D8)-$H$1,0) -> 0
A9: 45413 | B9: 350 | C9: 18.42 | E9: 6 | J9: =IF((C9+D9)>$H$1,(C9+D9)-$H$1,0) -> 3.42 | K9: Paid
A10: 45444 | B10: 350 | C10: 38.45 | E10: 6 | J10: =IF((C10+D10)>$H$1,(C10+D10)-$H$1,0) -> 23.45 | K10: Paid
A11: 45474 | B11: 350 | C11: 43.48 | E11: 6 | J11: =IF((C11+D11)>$H$1,(C11+D11)-$H$1,0) -> 28.48 | K11: Paid
A12: 45505 | B12: 350 | C12: 10.83 | E12: 6 | J12: =IF((C12+D12)>$H$1,(C12+D12)-$H$1,0) -> 0
A13: 45536 | B13: 350 | C13: 11.52 | E13: 6 | J13: =IF((C13+D13)>$H$1,(C13+D13)-$H$1,0) -> 0
A14: 45566 | B14: 350 | C14: 14.74 | E14: 6 | H14: 350 | I14: Deposit refund | J14: =IF((C14+D14)>$H$1,(C14+D14)-$H$1,0) -> 0
A15: 45597 | B15: 700 | C15: 15 | E15: 6 | H15: 350 | I15: Agent fees. EWA original bill 69.75bd | J15: =IF((C15+D15)>$H$1,(C15+D15)-$H$1,0) -> 0
A16: 45627 | B16: 350 | C16: 14.93 | E16: 6 | J16: =IF((C16+D16)>$H$1,(C16+D16)-$H$1,0) -> 0 | L16: =SUM(B5:B16)-SUM(C5:C16)-SUM(D5:D16)-SUM(E5:E16)-SUM(F5:F16)-SUM(G5:G16)-SUM(H5:H16)+SUM(J5:J16) -> 3609.77
A17: 45658 | B17: 350 | C17: 9.07 | E17: 6 | J17: =IF(C17>$H$1,C17-$H$1,0) -> 0
A18: 45689 | B18: 350 | C18: 13.98 | E18: 6 | H18: 231.55 | I18: Annual maintenance | J18: =IF(C18>$H$1,C18-$H$1,0) -> 0
A19: 45717 | B19: 350 | C19: 14.18 | E19: 6 | J19: =IF(C19>$H$1,C19-$H$1,0) -> 0
A20: 45748 | B20: 350 | C20: 11.84 | E20: 6 | J20: =IF(C20>$H$1,C20-$H$1,0) -> 0
A21: 45778 | B21: 350 | C21: 15.03 | E21: 6 | J21: =IF(C21>$H$1,C21-$H$1,0) -> 0.03
A22: 45809 | B22: 0 | C22: 14.3 | E22: 6 | H22: =350-145 -> 205 | I22: Deposit-comm | J22: =IF(C22>$H$1,C22-$H$1,0) -> 0
A23: 45839 | B23: 0 | C23: 9.44 | E23: 6 | J23: =IF(C23>$H$1,C23-$H$1,0) -> 0
A24: 45870 | B24: 0 | C24: 8.43 | E24: 6 | J24: =IF(C24>$H$1,C24-$H$1,0) -> 0
A25: 45901 | B25: 0 | C25: 7.24 | E25: 6 | J25: =IF(C25>$H$1,C25-$H$1,0) -> 0
A26: 45931 | B26: 0 | C26: 8.2 | E26: 6 | J26: =IF(C26>$H$1,C26-$H$1,0) -> 0
A27: 45962 | B27: 0 | C27: 5.85 | E27: 6 | H27: 3 | I27: Repair skirt light | J27: =IF(C27>$H$1,C27-$H$1,0) -> 0
A28: 45992 | B28: 0 | C28: 6.37 | E28: 6 | J28: =IF(C28>$H$1,C28-$H$1,0) -> 0 | L28: =SUM(B17:B28)-SUM(C17:C28)-SUM(D17:D28)-SUM(E17:E28)-SUM(F17:F28)-SUM(G17:G28)-SUM(H17:H28)+SUM(J17:J28) -> 1114.55
A29: 46023 | B29: 0 | E29: 6 | J29: =IF(C29>$H$1,C29-$H$1,0) -> 0
A30: 46054 | J30: =IF(C30>$H$1,C30-$H$1,0) -> 0
A31: 46082 | J31: =IF(C31>$H$1,C31-$H$1,0) -> 0
A32: 46113 | J32: =IF(C32>$H$1,C32-$H$1,0) -> 0
A33: 46143 | J33: =IF(C33>$H$1,C33-$H$1,0) -> 0
A34: 46174 | J34: =IF(C34>$H$1,C34-$H$1,0) -> 0
A35: 46204 | J35: =IF(C35>$H$1,C35-$H$1,0) -> 0
A36: 46235 | J36: =IF(C36>$H$1,C36-$H$1,0) -> 0
A37: 46266 | J37: =IF(C37>$H$1,C37-$H$1,0) -> 0
A38: 46296 | J38: =IF(C38>$H$1,C38-$H$1,0) -> 0
A39: 46327 | J39: =IF(C39>$H$1,C39-$H$1,0) -> 0
A40: 46357 | J40: =IF(C40>$H$1,C40-$H$1,0) -> 0 | L40: =SUM(B29:B40)-SUM(C29:C40)-SUM(D29:D40)-SUM(E29:E40)-SUM(F29:F40)-SUM(G29:G40)-SUM(H29:H40)+SUM(J29:J40) -> -6
...

Sheet 1306B
A1: Flat | B1: =Master!B4 -> 1306B | C1: Parking | D1: =Master!J4 -> P6-19 | E1: EWA | F1: =Master!N4 -> 1100318912 | G1: EWA limit | H1: =Master!O4 -> 20 | Q1: Flat | R1: 1306B | T1: EWA | U1: 1100318912
A2: Tenant | B2: =Master!C4 -> Zahraa | C2: Phone | D2: =Master!I4 -> 6666 8989 | E2: Lease Start | F2: =Master!K4 -> 45210 | G2: Lease end | H2: =Master!L4 -> 46305 | Q2: Tenant | R2: Zahraa | T2: EWA limit | U2: 20
A3: Month | B3: Rent | C3: EWA | D3: Chiller | E3: Internet | F3: Housekeeping | G3: Manage. fees | H3: Other fees | I3: Comments | J3: EWA Excess | K3: Excess pay | Q3: Month | S3: EWA | U3: EWA Excess
A4: Balance: | B4: 0 | C4: Balance Date: | D4: 45291 | Q4: 45778 | S4: 28.7 | U4: 8.7
A5: 45292 | B5: 480 | C5: 10.55 | D5: 0 | E5: 0 | F5: 0 | J5: =IF((C5+D5)>$H$1,(C5+D5)-$H$1,0) -> 0 | Q5: 45809 | S5: 37.31 | U5: 17.31
A6: 45323 | B6: 480 | C6: 14.35 | D6: 0 | E6: 0 | F6: 0 | H6: 463.1 | I6: Annual maintenance | J6: =IF((C6+D6)>$H$1,(C6+D6)-$H$1,0) -> 0 | Q6: 45839 | S6: 35.28 | U6: 15.28
A7: 45352 | B7: 480 | C7: 10 | D7: 0 | E7: 0 | F7: 0 | J7: =IF((C7+D7)>$H$1,(C7+D7)-$H$1,0) -> 0 | Q7: 45870 | S7: 44.6 | U7: 24.6
A8: 45383 | B8: 480 | C8: 11.54 | D8: 0 | E8: 0 | F8: 0 | J8: =IF((C8+D8)>$H$1,(C8+D8)-$H$1,0) -> 0 | Q8: 45901 | S8: 40.99 | U8: 20.99
A9: 45413 | B9: 480 | C9: 17.59 | D9: 0 | E9: 0 | F9: 0 | J9: =IF((C9+D9)>$H$1,(C9+D9)-$H$1,0) -> 0 | Q9: 45931 | S9: 33.88 | U9: 13.88
A10: 45444 | B10: 480 | C10: 40.26 | D10: 0 | E10: 0 | F10: 0 | J10: =IF((C10+D10)>$H$1,(C10+D10)-$H$1,0) -> 20.26 | K10: Paid | Q10: 45962 | S10: 26.58 | U10: 6.58
A11: 45474 | B11: 480 | C11: 46.29 | D11: 0 | E11: 0 | F11: 0 | J11: =IF((C11+D11)>$H$1,(C11+D11)-$H$1,0) -> 26.29 | K11: Paid | U11: 107.34
A12: 45505 | B12: 480 | C12: 43.74 | D12: 0 | E12: 0 | F12: 0 | J12: =IF((C12+D12)>$H$1,(C12+D12)-$H$1,0) -> 23.74 | K12: Paid
A13: 45536 | B13: 480 | C13: 34.7 | D13: 0 | E13: 0 | F13: 0 | J13: =IF((C13+D13)>$H$1,(C13+D13)-$H$1,0) -> 14.7 | K13: Paid
A14: 45566 | B14: 480 | C14: 28.41 | D14: 0 | E14: 0 | F14: 0 | J14: =IF((C14+D14)>$H$1,(C14+D14)-$H$1,0) -> 8.41 | K14: Paid
A15: 45597 | B15: 480 | C15: 21.38 | D15: 0 | E15: 0 | F15: 0 | J15: =IF((C15+D15)>$H$1,(C15+D15)-$H$1,0) -> 1.38 | K15: Paid
A16: 45627 | B16: 480 | C16: 14.35 | D16: 0 | E16: 0 | F16: 0 | J16: =IF((C16+D16)>$H$1,(C16+D16)-$H$1,0) -> 0 | L16: =SUM(B5:B16)-SUM(C5:C16)-SUM(D5:D16)-SUM(E5:E16)-SUM(F5:F16)-SUM(G5:G16)-SUM(H5:H16)+SUM(J5:J16) -> 5098.52
A17: 45658 | B17: 480 | C17: 16.42 | J17: =IF(C17>$H$1,C17-$H$1,0) -> 0
A18: 45689 | B18: 480 | C18: 16.77 | H18: 463.1 | I18: Annual maintenance | J18: =IF(C18>$H$1,C18-$H$1,0) -> 0
A19: 45717 | B19: 480 | C19: 13.5 | J19: =IF(C19>$H$1,C19-$H$1,0) -> 0
A20: 45748 | B20: 480 | C20: 18.03 | J20: =IF(C20>$H$1,C20-$H$1,0) -> 0
A21: 45778 | B21: 480 | C21: 28.7 | J21: =IF(C21>$H$1,C21-$H$1,0) -> 8.7
A22: 45809 | B22: 480 | C22: 37.31 | J22: =IF(C22>$H$1,C22-$H$1,0) -> 17.31
A23: 45839 | B23: 480 | C23: 35.28 | J23: =IF(C23>$H$1,C23-$H$1,0) -> 15.28
A24: 45870 | B24: 480 | C24: 44.6 | J24: =IF(C24>$H$1,C24-$H$1,0) -> 24.6
A25: 45901 | B25: 480 | C25: 40.99 | J25: =IF(C25>$H$1,C25-$H$1,0) -> 20.99
A26: 45931 | B26: 480 | C26: 33.88 | J26: =IF(C26>$H$1,C26-$H$1,0) -> 13.88
A27: 45962 | B27: 480 | C27: 26.58 | J27: =IF(C27>$H$1,C27-$H$1,0) -> 6.58
A28: 45992 | B28: 480 | C28: 19.71 | J28: =IF(C28>$H$1,C28-$H$1,0) -> 0 | L28: =SUM(B17:B28)-SUM(C17:C28)-SUM(D17:D28)-SUM(E17:E28)-SUM(F17:F28)-SUM(G17:G28)-SUM(H17:H28)+SUM(J17:J28) -> 5072.47
A29: 46023 | B29: 480 | J29: =IF(C29>$H$1,C29-$H$1,0) -> 0
A30: 46054 | J30: =IF(C30>$H$1,C30-$H$1,0) -> 0
A31: 46082 | J31: =IF(C31>$H$1,C31-$H$1,0) -> 0
A32: 46113 | J32: =IF(C32>$H$1,C32-$H$1,0) -> 0
A33: 46143 | J33: =IF(C33>$H$1,C33-$H$1,0) -> 0
A34: 46174 | J34: =IF(C34>$H$1,C34-$H$1,0) -> 0
A35: 46204 | J35: =IF(C35>$H$1,C35-$H$1,0) -> 0
A36: 46235 | J36: =IF(C36>$H$1,C36-$H$1,0) -> 0
A37: 46266 | J37: =IF(C37>$H$1,C37-$H$1,0) -> 0
A38: 46296 | J38: =IF(C38>$H$1,C38-$H$1,0) -> 0
A39: 46327 | J39: =IF(C39>$H$1,C39-$H$1,0) -> 0
A40: 46357 | J40: =IF(C40>$H$1,C40-$H$1,0) -> 0 | L40: =SUM(B29:B40)-SUM(C29:C40)-SUM(D29:D40)-SUM(E29:E40)-SUM(F29:F40)-SUM(G29:G40)-SUM(H29:H40)+SUM(J29:J40) -> 480
...

Sheet 1509B
A1: Flat | B1: =Master!B5 -> 1509B | C1: Parking | D1: =Master!J5 -> P6-48 | E1: EWA | F1: =Master!N5 -> 1100119864 | G1: EWA limit | H1: =Master!O5 -> 15 | N1: Flat | O1: =Master!B5 -> 1509B | Q1: EWA | R1: =Master!N5 -> 1100119864
A2: Tenant | B2: =Master!C5 -> Sultan | C2: Phone | D2: =Master!I5 -> 560490705 | E2: Lease Start | F2: =Master!K5 -> 45532 | G2: Lease end | H2: =Master!L5 -> 45896 | N2: Tenant | O2: =Master!C5 -> Sultan | Q2: EWA limit | R2: =Master!O5 -> 15
A3: Month | B3: Rent | C3: EWA | D3: Chiller | E3: Internet | F3: Housekeeping | G3: Manage. fees | H3: Other fees | I3: Comments | J3: EWA Excess | K3: Excess pay | N3: Month | P3: EWA | R3: EWA Excess
A4: Balance: | B4: 0 | C4: Balance Date: | D4: 45291 | N4: 45778 | P4: 17.47 | R4: =P4-$R$2 -> 2.47
A5: 45292 | B5: =Master!$M$5 -> 350 | C5: 10.14 | E5: 6 | J5: =IF(C5>$H$1,C5-$H$1,0) -> 0 | N5: 45809 | P5: 19.5 | R5: =P5-$R$2 -> 4.5
A6: 45323 | B6: =Master!$M$5 -> 350 | C6: 10.08 | E6: 6 | J6: =IF(C6>$H$1,C6-$H$1,0) -> 0 | N6: 45839 | P6: 18.84 | R6: =P6-$R$2 -> 3.84
A7: 45352 | B7: =Master!$M$5 -> 350 | C7: 7.16 | E7: 6 | J7: =IF(C7>$H$1,C7-$H$1,0) -> 0 | N7: 45870 | P7: 20.9 | R7: =P7-$R$2 -> 5.9
A8: 45383 | B8: =Master!$M$5 -> 350 | C8: 7.45 | E8: 6 | J8: =IF(C8>$H$1,C8-$H$1,0) -> 0 | N8: 45901 | P8: 19.25 | R8: =P8-$R$2 -> 4.25
A9: 45413 | B9: =Master!$M$5 -> 350 | C9: 15.06 | E9: 6 | J9: 0 | N9: 45931 | P9: 15.27 | R9: =P9-$R$2 -> 0.27
A10: 45444 | B10: =Master!$M$5 -> 350 | C10: 11.16 | E10: 6 | J10: =IF(C10>$H$1,C10-$H$1,0) -> 0 | R10: =SUM(R4:R9) -> 21.23
A11: 45474 | B11: 0 | C11: 9.62 | E11: 6 | J11: =IF(C11>$H$1,C11-$H$1,0) -> 0
A12: 45505 | B12: 0 | C12: 6.98 | E12: 6 | J12: =IF(C12>$H$1,C12-$H$1,0) -> 0
A13: 45536 | B13: =Master!$M$5 -> 350 | C13: 18.94 | E13: 6 | J13: =IF(C13>$H$1,C13-$H$1,0) -> 3.94 | K13: Paid
A14: 45566 | B14: =Master!$M$5 -> 350 | C14: 24.13 | E14: 6 | J14: =IF(C14>$H$1,C14-$H$1,0) -> 9.13 | K14: Paid
A15: 45597 | B15: 350 | C15: 19.32 | E15: 6 | J15: =IF(C15>$H$1,C15-$H$1,0) -> 4.32 | K15: Paid
A16: 45627 | B16: =Master!$M$5 -> 350 | C16: 12.49 | E16: 6 | J16: =IF(C16>$H$1,C16-$H$1,0) -> 0 | L16: =SUM(B5:B16)-SUM(C5:C16)-SUM(D5:D16)-SUM(E5:E16)-SUM(F5:F16)-SUM(G5:G16)-SUM(H5:H16)+SUM(J5:J16) -> 3292.86
A17: 45658 | B17: 350 | C17: 8.58 | E17: 6 | J17: =IF(C17>$H$1,C17-$H$1,0) -> 0
A18: 45689 | B18: 350 | C18: 9.65 | E18: 6 | H18: 231.55 | I18: Annual maintenance | J18: =IF(C18>$H$1,C18-$H$1,0) -> 0
A19: 45717 | B19: 350 | C19: 11.64 | E19: 6 | J19: =IF(C19>$H$1,C19-$H$1,0) -> 0
A20: 45748 | B20: 350 | C20: 9.44 | E20: 6 | J20: =IF(C20>$H$1,C20-$H$1,0) -> 0
A21: 45778 | B21: 350 | C21: 17.47 | E21: 6 | J21: =IF(C21>$H$1,C21-$H$1,0) -> 2.47
A22: 45809 | B22: 350 | C22: 19.5 | E22: 6 | J22: =IF(C22>$H$1,C22-$H$1,0) -> 4.5
A23: 45839 | B23: 350 | C23: 18.84 | E23: 6 | J23: =IF(C23>$H$1,C23-$H$1,0) -> 3.84
A24: 45870 | B24: 350 | C24: 20.9 | E24: 6 | J24: =IF(C24>$H$1,C24-$H$1,0) -> 5.9
A25: 45901 | B25: 350 | C25: 19.25 | E25: 6 | J25: =IF(C25>$H$1,C25-$H$1,0) -> 4.25
A26: 45931 | B26: 350 | C26: 15.27 | E26: 6 | J26: =IF(C26>$H$1,C26-$H$1,0) -> 0.27
A27: 45962 | B27: 350 | C27: 10.72 | E27: 6 | J27: =IF(C27>$H$1,C27-$H$1,0) -> 0
A28: 45992 | B28: 350 | C28: 10.49 | E28: 6 | J28: =IF(C28>$H$1,C28-$H$1,0) -> 0 | L28: =SUM(B17:B28)-SUM(C17:C28)-SUM(D17:D28)-SUM(E17:E28)-SUM(F17:F28)-SUM(G17:G28)-SUM(H17:H28)+SUM(J17:J28) -> 3745.93
A29: 46023 | B29: 350 | E29: 6 | J29: =IF(C29>$H$1,C29-$H$1,0) -> 0
A30: 46054 | J30: =IF(C30>$H$1,C30-$H$1,0) -> 0
A31: 46082 | J31: =IF(C31>$H$1,C31-$H$1,0) -> 0
A32: 46113 | J32: =IF(C32>$H$1,C32-$H$1,0) -> 0
A33: 46143 | J33: =IF(C33>$H$1,C33-$H$1,0) -> 0
A34: 46174 | J34: =IF(C34>$H$1,C34-$H$1,0) -> 0
A35: 46204 | J35: =IF(C35>$H$1,C35-$H$1,0) -> 0
A36: 46235 | J36: =IF(C36>$H$1,C36-$H$1,0) -> 0
A37: 46266 | J37: =IF(C37>$H$1,C37-$H$1,0) -> 0
A38: 46296 | J38: =IF(C38>$H$1,C38-$H$1,0) -> 0
A39: 46327 | J39: =IF(C39>$H$1,C39-$H$1,0) -> 0
A40: 46357 | J40: =IF(C40>$H$1,C40-$H$1,0) -> 0 | L40: =SUM(B29:B40)-SUM(C29:C40)-SUM(D29:D40)-SUM(E29:E40)-SUM(F29:F40)-SUM(G29:G40)-SUM(H29:H40)+SUM(J29:J40) -> 344
...

Sheet 2206B
A1: Flat | B1: =Master!B6 -> 2206B | C1: Parking | D1: =Master!J6 -> P3-41 | E1: EWA | F1: =Master!N6 -> 1100331105 | G1: EWA limit | H1: =Master!O6 -> 25
A2: Tenant | B2: =Master!C6 -> Abdulaziz | C2: Phone | D2: =Master!I6 -> 552427972 | E2: Lease Start | F2: =Master!K6 -> 45918 | G2: Lease end | H2: =Master!L6 -> 46282
A3: Month | B3: Rent | C3: EWA | D3: Chiller | E3: Internet | F3: Housekeeping | G3: Manage. fees | H3: Other fees | I3: Comments | J3: Payment to owner | K3: EWA Excess | L3: Excess pay
A4: Balance: | B4: 3233.26 | C4: Balance Date: | D4: 45291
A5: 45292 | B5: =Master!$M$6 -> 540 | C5: 15.7 | D5: 0 | E5: 15.3 | F5: 0 | G5: 25 | K5: =IF((C5+D5)>$H$1,(C5+D5)-$H$1,0) -> 0
A6: 45323 | B6: =Master!$M$6 -> 540 | C6: 14.42 | D6: 0 | E6: 15.3 | F6: 0 | G6: 25 | K6: =IF((C6+D6)>$H$1,(C6+D6)-$H$1,0) -> 0
A7: 45352 | B7: =Master!$M$6 -> 540 | C7: 14.2 | D7: 0 | E7: 15.3 | F7: 0 | G7: 25 | K7: =IF((C8+D8)>$H$1,(C8+D8)-$H$1,0) -> 0
A8: 45383 | B8: =Master!$M$6 -> 540 | C8: 13.42 | D8: 0 | E8: 15.3 | F8: 0 | G8: 25 | K8: =IF((C8+D8)>$H$1,(C8+D8)-$H$1,0) -> 0
A9: 45413 | B9: =Master!$M$6 -> 540 | C9: 16.86 | D9: 0 | E9: 15.3 | F9: 0 | G9: 25 | H9: 4000 | I9: Cash to Rami | K9: =IF((C9+D9)>$H$1,(C9+D9)-$H$1,0) -> 0
A10: 45444 | B10: =Master!$M$6 -> 540 | C10: 15.1 | D10: 0 | E10: 15.3 | F10: 0 | G10: 25 | K10: =IF((C10+D10)>$H$1,(C10+D10)-$H$1,0) -> 0
A11: 45474 | B11: =Master!$M$6 -> 540 | C11: 30.43 | D11: 0 | E11: 15.3 | F11: 0 | G11: 25 | K11: =IF((C11+D11)>$H$1,(C11+D11)-$H$1,0) -> 5.43 | L11: Paid
A12: 45505 | B12: =Master!$M$6 -> 540 | C12: 32.38 | D12: 0 | E12: 15.3 | F12: 0 | G12: 25 | K12: =IF((C12+D12)>$H$1,(C12+D12)-$H$1,0) -> 7.38 | L12: Paid
A13: 45536 | B13: =Master!$M$6 -> 540 | C13: 24.75 | D13: 0 | E13: 15.3 | F13: 0 | G13: 25 | H13: 118.2 | I13: Notary office | K13: =IF((C13+D13)>$H$1,(C13+D13)-$H$1,0) -> 0
A14: 45566 | B14: =Master!$M$6 -> 540 | C14: 23.19 | D14: 0 | E14: 15.3 | F14: 0 | G14: 25 | H14: 1157 | I14: SLRB 1.7% | K14: =IF((C14+D14)>$H$1,(C14+D14)-$H$1,0) -> 0
A15: 45597 | B15: =Master!$M$6 -> 540 | C15: 20.18 | D15: 0 | E15: 15.3 | F15: 0 | G15: 25 | H15: 150 | I15: Shared cost | K15: =IF((C15+D15)>$H$1,(C15+D15)-$H$1,0) -> 0
A16: 45627 | B16: =Master!$M$6 -> 540 | C16: 13.12 | D16: 0 | E16: 15.3 | F16: 0 | G16: 25 | H16: 2603.52 | I16: Transfer to rami 1/7/25 | K16: =IF((C16+D16)>$H$1,(C16+D16)-$H$1,0) -> 0 | M16: =SUM(B5:B16)-SUM(C5:C16)-SUM(D5:D16)-SUM(E5:E16)-SUM(F5:F16)-SUM(G5:G16)-SUM(H5:H16)+SUM(K5:K16) -> -2253.26
B17: =SUM(B5:B16) -> 6480 | C17: =SUM(C5:C16) -> 233.75 | D17: =SUM(D5:D16) -> 0 | E17: =SUM(E5:E16) -> 183.6 | F17: =SUM(F5:F16) -> 0 | G17: =SUM(G5:G16) -> 300 | H17: =SUM(H5:H16) -> 8028.72 | K17: =SUM(K5:K16) -> 12.81
A18: Net | B18: =B17-C17-D17-E17-F17-G17-H17+K17 -> -2253.26
A19: Balance: | B19: =B4+B18 -> 980 | C19: Balance Date: | D19: 45657
A20: 45658 | B20: =Master!$M$6 -> 540 | C20: 18.8 | D20: 0 | E20: 15.3 | F20: 0 | G20: 25 | K20: =IF((C20+D20)>$H$1,(C20+D20)-$H$1,0) -> 0
A21: 45689 | B21: 500 | C21: 17.52 | D21: 0 | E21: 15.3 | F21: 0 | G21: 25 | H21: 463.1 | I21: Annual maintenance | J21: 400 | K21: =IF((C21+D21)>$H$1,(C21+D21)-$H$1,0) -> 0
A22: 45717 | B22: 500 | C22: 19.06 | D22: 0 | E22: 15.3 | F22: 0 | G22: 25 | J22: 400 | K22: =IF((C23+D23)>$H$1,(C23+D23)-$H$1,0) -> 0
A23: 45748 | B23: 500 | C23: 11.67 | D23: 0 | E23: 15.3 | F23: 0 | G23: 25 | J23: 400 | K23: =IF((C23+D23)>$H$1,(C23+D23)-$H$1,0) -> 0
A24: 45778 | B24: 500 | C24: 19.76 | D24: 0 | E24: 15.3 | F24: 0 | G24: 25 | J24: 400 | K24: =IF((C24+D24)>$H$1,(C24+D24)-$H$1,0) -> 0
A25: 45809 | B25: 500 | C25: 24.57 | D25: 0 | E25: 16.18 | F25: 0 | G25: 25 | J25: 400 | K25: =IF((C25+D25)>$H$1,(C25+D25)-$H$1,0) -> 0
A26: 45839 | B26: 500 | C26: 26.74 | D26: 0 | E26: 16.18 | F26: 0 | G26: 25 | J26: 400 | K26: =IF((C26+D26)>$H$1,(C26+D26)-$H$1,0) -> 1.74 | L26: Not paid
A27: 45870 | B27: 500 | C27: 26.4 | D27: 0 | E27: 16.18 | F27: 0 | G27: 25 | J27: 400 | K27: =IF((C27+D27)>$H$1,(C27+D27)-$H$1,0) -> 1.4 | L27: Not paid
A28: 45901 | B28: 1080 | C28: 24.75 | D28: 0 | E28: 16.18 | F28: 0 | G28: 27 | H28: =30+12+10+11+8+30 -> 101 | I28: Flat repairs | J28: 400 | K28: =IF((C28+D28)>$H$1,(C28+D28)-$H$1,0) -> 0
A29: 45931 | B29: -500 | C29: 0 | D29: 0 | E29: 16.18 | F29: 0 | G29: 27 | H29: 540 | I29: Commission to agent | J29: 400 | K29: =IF((C29+D29)>$H$1,(C29+D29)-$H$1,0) -> 0
A30: 45962 | B30: 0 | C30: 0 | D30: 0 | E30: 16.18 | F30: 0 | G30: 27 | H30: 60 | I30: Bed+cleaning | K30: =IF((C30+D30)>$H$1,(C30+D30)-$H$1,0) -> 0
A31: 45992 | D31: 0 | F31: 0 | G31: 27 | K31: =IF((C31+D31)>$H$1,(C31+D31)-$H$1,0) -> 0 | M31: =SUM(B20:B31)-SUM(C20:C31)-SUM(D20:D31)-SUM(E20:E31)-SUM(F20:F31)-SUM(G20:G31)-SUM(H20:H31)+SUM(K20:K31) -> 2788.19
B32: =SUM(B20:B31) -> 4620 | C32: =SUM(C20:C31) -> 189.27 | D32: =SUM(D20:D31) -> 0 | E32: =SUM(E20:E31) -> 173.58 | F32: =SUM(F20:F31) -> 0 | G32: =SUM(G20:G31) -> 308 | H32: =SUM(H20:H31) -> 1164.1 | J32: =SUM(J20:J31) -> 3600
A33: Net | B33: =B32-C32-D32-E32-F32-G32-H32+K32 -> 2785.05
A34: Balance: | B34: =B19+B33-J32 -> 165.05 | C34: Balance Date: | D34: =TODAY() -> 46029

Sheet 2306B
A1: Flat | B1: =Master!B7 -> 2306B | C1: Parking | D1: =Master!J7 -> P3-40 | E1: EWA | F1: =Master!N7 -> 1100297470 | G1: EWA limit | H1: =Master!O7 -> 30 | N1: Flat | O1: =Master!B7 -> 2306B | Q1: EWA | R1: =Master!N7 -> 1100297470
A2: Tenant | B2: =Master!C7 -> Loai | C2: Phone | D2: =Master!I7 -> 6694 4446 | E2: Lease Start | F2: =Master!K7 -> 45017 | G2: Lease end | H2: =Master!L7 -> 46112 | N2: Tenant | O2: =Master!C7 -> Loai | Q2: EWA limit | R2: =Master!O7 -> 30
A3: Month | B3: Rent | C3: EWA | D3: Chiller | E3: Internet | F3: Housekeeping | G3: Manage. fees | H3: Other fees | I3: Comments | J3: EWA Excess | K3: Status | N3: Month | P3: EWA | R3: EWA Excess
A4: Balance: | B4: 0 | C4: Balance Date: | D4: 45291 | N4: 45778 | P4: 36.64 | R4: =P4-$R$2 -> 6.64
A5: 45017 | B5: =Master!$M$7 -> 480 | D5: 0 | E5: =Master!$P$7 -> 0 | J5: =IF(C5>$H$1,C5-$H$1,0) -> 0 | N5: 45809 | P5: 43.75 | R5: =P5-$R$2 -> 13.75
A6: 45047 | B6: =Master!$M$7 -> 480 | D6: 0 | E6: =Master!$P$7 -> 0 | J6: =IF(C6>$H$1,C6-$H$1,0) -> 0 | N6: 45839 | P6: 54.38 | R6: =P6-$R$2 -> 24.38
A7: 45078 | B7: =Master!$M$7 -> 480 | C7: 32.74 | D7: 0 | E7: =Master!$P$7 -> 0 | J7: =IF(C7>$H$1,C7-$H$1,0) -> 2.74 | K7: Paid | N7: 45870 | P7: 55.63 | R7: =P7-$R$2 -> 25.63
A8: 45108 | B8: =Master!$M$7 -> 480 | C8: 39.42 | D8: 0 | E8: =Master!$P$7 -> 0 | J8: =IF(C8>$H$1,C8-$H$1,0) -> 9.42 | K8: Paid | N8: 45901 | P8: 50.32 | R8: =P8-$R$2 -> 20.32
A9: 45139 | B9: =Master!$M$7 -> 480 | C9: 39.73 | D9: 0 | E9: =Master!$P$7 -> 0 | J9: =IF(C9>$H$1,C9-$H$1,0) -> 9.73 | K9: Paid | N9: 45931 | P9: 46.35 | R9: =P9-$R$2 -> 16.35
A10: 45170 | B10: =Master!$M$7 -> 480 | D10: 0 | E10: =Master!$P$7 -> 0 | J10: =IF(C10>$H$1,C10-$H$1,0) -> 0 | N10: 45962 | P10: 33.15 | R10: =P10-$R$2 -> 3.15
A11: 45200 | B11: =Master!$M$7 -> 480 | D11: 0 | E11: =Master!$P$7 -> 0 | J11: =IF(C11>$H$1,C11-$H$1,0) -> 0 | R11: =SUM(R4:R10) -> 110.22
A12: 45231 | B12: =Master!$M$7 -> 480 | D12: 0 | E12: =Master!$P$7 -> 0 | J12: =IF(C12>$H$1,C12-$H$1,0) -> 0
A13: 45261 | B13: =Master!$M$7 -> 480 | C13: 16.68 | D13: 0 | E13: =Master!$P$7 -> 0 | J13: =IF(C13>$H$1,C13-$H$1,0) -> 0 | L13: =SUM(B5:B13)-SUM(C5:C13)-SUM(D5:D13)-SUM(E5:E13)-SUM(F5:F13)-SUM(G5:G13)-SUM(H5:H13)+SUM(J5:J13) -> 4213.32
A14: 45292 | B14: =Master!$M$7 -> 480 | C14: 14.98 | D14: 0 | E14: =Master!$P$7 -> 0 | J14: =IF(C14>$H$1,C14-$H$1,0) -> 0
A15: 45323 | B15: =Master!$M$7 -> 480 | C15: 13.12 | D15: 0 | E15: =Master!$P$7 -> 0 | H15: 463.1 | I15: Annual maintenance | J15: =IF(C15>$H$1,C15-$H$1,0) -> 0
A16: 45352 | B16: =Master!$M$7 -> 480 | C16: 15.99 | D16: 0 | E16: =Master!$P$7 -> 0 | J16: =IF(C16>$H$1,C16-$H$1,0) -> 0
A17: 45383 | B17: =Master!$M$7 -> 480 | C17: 18.22 | D17: 0 | E17: =Master!$P$7 -> 0 | J17: =IF(C17>$H$1,C17-$H$1,0) -> 0
A18: 45413 | B18: =Master!$M$7 -> 480 | C18: 26.61 | D18: 0 | E18: =Master!$P$7 -> 0 | J18: =IF(C18>$H$1,C18-$H$1,0) -> 0
A19: 45444 | B19: =Master!$M$7 -> 480 | C19: 42.12 | D19: 0 | E19: =Master!$P$7 -> 0 | J19: =IF(C19>$H$1,C19-$H$1,0) -> 12.12 | K19: Paid
A20: 45474 | B20: =Master!$M$7 -> 480 | C20: 43.89 | D20: 0 | E20: =Master!$P$7 -> 0 | J20: =IF(C20>$H$1,C20-$H$1,0) -> 13.89 | K20: Paid
A21: 45505 | B21: =Master!$M$7 -> 480 | C21: 47.89 | D21: 0 | E21: =Master!$P$7 -> 0 | J21: =IF(C21>$H$1,C21-$H$1,0) -> 17.89 | K21: Paid
A22: 45536 | B22: =Master!$M$7 -> 480 | C22: 51.81 | D22: 0 | E22: =Master!$P$7 -> 0 | J22: =IF(C22>$H$1,C22-$H$1,0) -> 21.81 | K22: Paid
A23: 45566 | B23: =Master!$M$7 -> 480 | C23: 42.73 | D23: 0 | E23: =Master!$P$7 -> 0 | J23: =IF(C23>$H$1,C23-$H$1,0) -> 12.73 | K23: Paid
A24: 45597 | B24: =Master!$M$7 -> 480 | C24: 28.17 | D24: 0 | E24: =Master!$P$7 -> 0 | J24: =IF(C24>$H$1,C24-$H$1,0) -> 0
A25: 45627 | B25: =Master!$M$7 -> 480 | C25: 17.9 | D25: 0 | E25: =Master!$P$7 -> 0 | J25: =IF(C25>$H$1,C25-$H$1,0) -> 0 | L25: =SUM(B14:B25)-SUM(C14:C25)-SUM(D14:D25)-SUM(E14:E25)-SUM(F14:F25)-SUM(G14:G25)-SUM(H14:H25)+SUM(J14:J25) -> 5011.91
A26: 45658 | B26: =Master!$M$7 -> 480 | C26: 16.57 | D26: 0 | E26: =Master!$P$7 -> 0 | J26: =IF(C26>$H$1,C26-$H$1,0) -> 0
A27: 45689 | B27: 480 | C27: 15.75 | D27: 0 | E27: =Master!$P$7 -> 0 | H27: 463.1 | I27: Annual maintenance | J27: =IF(C27>$H$1,C27-$H$1,0) -> 0
A28: 45717 | B28: 480 | C28: 17.11 | D28: 0 | E28: =Master!$P$7 -> 0 | J28: =IF(C28>$H$1,C28-$H$1,0) -> 0
A29: 45748 | B29: 480 | C29: 25.71 | D29: 0 | E29: =Master!$P$7 -> 0 | J29: =IF(C29>$H$1,C29-$H$1,0) -> 0
A30: 45778 | B30: 480 | C30: 36.64 | D30: 0 | E30: =Master!$P$7 -> 0 | J30: =IF(C30>$H$1,C30-$H$1,0) -> 6.64
A31: 45809 | B31: 480 | C31: 43.75 | D31: 0 | E31: =Master!$P$7 -> 0 | J31: =IF(C31>$H$1,C31-$H$1,0) -> 13.75
A32: 45839 | B32: 480 | C32: 54.38 | D32: 0 | E32: =Master!$P$7 -> 0 | J32: =IF(C32>$H$1,C32-$H$1,0) -> 24.38
A33: 45870 | B33: 480 | C33: 55.63 | D33: 0 | E33: =Master!$P$7 -> 0 | J33: =IF(C33>$H$1,C33-$H$1,0) -> 25.63
A34: 45901 | B34: 480 | C34: 50.32 | D34: 0 | E34: =Master!$P$7 -> 0 | J34: =IF(C34>$H$1,C34-$H$1,0) -> 20.32
A35: 45931 | B35: 480 | C35: 46.35 | D35: 0 | E35: =Master!$P$7 -> 0 | J35: =IF(C35>$H$1,C35-$H$1,0) -> 16.35
A36: 45962 | B36: 480 | C36: 33.15 | D36: 0 | E36: =Master!$P$7 -> 0 | J36: =IF(C36>$H$1,C36-$H$1,0) -> 3.15
A37: 45992 | B37: 480 | C37: 25.88 | D37: 0 | E37: =Master!$P$7 -> 0 | J37: =IF(C37>$H$1,C37-$H$1,0) -> 0 | L37: =SUM(B26:B37)-SUM(C26:C37)-SUM(D26:D37)-SUM(E26:E37)-SUM(F26:F37)-SUM(G26:G37)-SUM(H26:H37)+SUM(J26:J37) -> 4985.88
A38: 46023 | B38: 480 | J38: =IF(C38>$H$1,C38-$H$1,0) -> 0
A39: 46054 | J39: =IF(C39>$H$1,C39-$H$1,0) -> 0
A40: 46082 | J40: =IF(C40>$H$1,C40-$H$1,0) -> 0
...

Sheet 2706B 
A1: Flat | B1: =Master!B8 -> 2706B | C1: Parking | D1: =Master!J8 -> P2-30 | E1: EWA | F1: =Master!N8 -> 1100290012 | G1: EWA limit | H1: =Master!O8 -> 20
A2: Tenant | B2: =Master!C8 -> Mike | C2: Phone | D2: =Master!I8 -> 3944 4700 | E2: Lease Start | F2: =Master!K8 -> 45862 | G2: Lease end | H2: =Master!L8 -> 46226
A3: Month | B3: Rent | C3: EWA | D3: Chiller | E3: Internet | F3: Housekeeping | G3: Manage. fees | H3: Other fees | I3: Comments | J3: EWA Excess | K3: Excess pay
A4: Balance: | B4: 0 | C4: Balance Date: | D4: 45291
A5: 45292 | B5: 480 | C5: 14.67 | D5: 0 | E5: 6 | J5: =IF(C5>$H$1,C5-$H$1,0) -> 0
A6: 45323 | B6: 480 | C6: 21.27 | D6: 0 | E6: 6 | J6: =IF(C6>$H$1,C6-$H$1,0) -> 1.27
A7: 45352 | B7: 480 | C7: 16.59 | D7: 0 | E7: 6 | H7: 480 | I7: Deposit refund | J7: =IF(C7>$H$1,C7-$H$1,0) -> 0
A8: 45383 | B8: =Master!$M$8 -> 560 | C8: 10.38 | D8: 0 | E8: 6 | J8: =IF(C8>$H$1,C8-$H$1,0) -> 0
A9: 45413 | B9: =Master!$M$8 -> 560 | C9: 16.05 | D9: 0 | E9: 6 | J9: =IF(C9>$H$1,C9-$H$1,0) -> 0
A10: 45444 | B10: =Master!$M$8 -> 560 | C10: 24.32 | D10: 0 | E10: 6 | J10: =IF(C10>$H$1,C10-$H$1,0) -> 4.32
A11: 45474 | B11: =Master!$M$8 -> 560 | C11: 40.12 | D11: 0 | E11: 6 | J11: =IF(C11>$H$1,C11-$H$1,0) -> 20.12 | K11: Paid
A12: 45505 | B12: =Master!$M$8 -> 560 | C12: 40.52 | D12: 0 | E12: 6 | J12: =IF(C12>$H$1,C12-$H$1,0) -> 20.52 | K12: Paid
A13: 45536 | B13: =Master!$M$8 -> 560 | C13: 34.5 | D13: 0 | E13: 6 | J13: =IF(C13>$H$1,C13-$H$1,0) -> 14.5 | K13: Paid
A14: 45566 | B14: =Master!$M$8 -> 560 | C14: 27.74 | D14: 0 | E14: 6 | J14: =IF(C14>$H$1,C14-$H$1,0) -> 7.74
A15: 45597 | B15: =Master!$M$8 -> 560 | C15: 21.82 | D15: 0 | E15: 6 | J15: =IF(C15>$H$1,C15-$H$1,0) -> 1.82
A16: 45627 | B16: =Master!$M$8 -> 560 | C16: 14.02 | D16: 0 | E16: 6 | J16: =IF(C16>$H$1,C16-$H$1,0) -> 0 | L16: =SUM(B5:B16)-SUM(C5:C16)-SUM(D5:D16)-SUM(E5:E16)-SUM(F5:F16)-SUM(G5:G16)-SUM(H5:H16)+SUM(J5:J16) -> 5716.29
A17: 45658 | B17: 550 | C17: 14.13 | E17: 6 | J17: =IF(C17>$H$1,C17-$H$1,0) -> 0
A18: 45689 | B18: 550 | C18: 9.39 | E18: 6 | H18: 463.1 | I18: Annual maintenance | J18: =IF(C18>$H$1,C18-$H$1,0) -> 0
A19: 45717 | B19: 550 | C19: 9.39 | E19: 6 | J19: =IF(C19>$H$1,C19-$H$1,0) -> 0
A20: 45748 | B20: 550 | C20: 12.4 | E20: 6 | J20: =IF(C20>$H$1,C20-$H$1,0) -> 0
A21: 45778 | B21: 550 | C21: 22.54 | E21: 6
A22: 45809 | B22: =550/2 -> 275 | C22: 30.06 | E22: 6 | I22: Rented for half month
A23: 45839 | B23: 550 | C23: 10.32 | E23: 6 | J23: =IF(C23>$H$1,C23-$H$1,0) -> 0
A24: 45870 | B24: 560 | C24: 17.39 | E24: 6 | J24: =IF(C24>$H$1,C24-$H$1,0) -> 0
A25: 45901 | B25: 560 | C25: 28.58 | E25: 6 | H25: 35 | I25: Washer repair | J25: =IF(C25>$H$1,C25-$H$1,0) -> 8.58
A26: 45931 | B26: 560 | C26: 18.37 | E26: 6 | H26: 35 | I26: fridge repair | J26: =IF(C26>$H$1,C26-$H$1,0) -> 0
A27: 45962 | B27: 560 | C27: 13.53 | E27: 6 | J27: =IF(C27>$H$1,C27-$H$1,0) -> 0
A28: 45992 | B28: 560 | C28: 15.35 | E28: 6 | J28: =IF(C28>$H$1,C28-$H$1,0) -> 0 | L28: =SUM(B17:B28)-SUM(C17:C28)-SUM(D17:D28)-SUM(E17:E28)-SUM(F17:F28)-SUM(G17:G28)-SUM(H17:H28)+SUM(J17:J28) -> 5577.03
A29: 46023 | B29: 560 | E29: 6 | J29: =IF(C29>$H$1,C29-$H$1,0) -> 0
A30: 46054 | H30: 463.1 | I30: Annual maintenance | J30: =IF(C30>$H$1,C30-$H$1,0) -> 0
A31: 46082 | J31: =IF(C31>$H$1,C31-$H$1,0) -> 0
A32: 46113 | J32: =IF(C32>$H$1,C32-$H$1,0) -> 0
A33: 46143 | J33: =IF(C33>$H$1,C33-$H$1,0) -> 0
A34: 46174 | J34: =IF(C34>$H$1,C34-$H$1,0) -> 0
A35: 46204 | J35: =IF(C35>$H$1,C35-$H$1,0) -> 0
A36: 46235 | J36: =IF(C36>$H$1,C36-$H$1,0) -> 0
A37: 46266 | J37: =IF(C37>$H$1,C37-$H$1,0) -> 0
A38: 46296 | J38: =IF(C38>$H$1,C38-$H$1,0) -> 0
A39: 46327 | J39: =IF(C39>$H$1,C39-$H$1,0) -> 0
A40: 46357 | J40: =IF(C40>$H$1,C40-$H$1,0) -> 0 | L40: =SUM(B29:B40)-SUM(C29:C40)-SUM(D29:D40)-SUM(E29:E40)-SUM(F29:F40)-SUM(G29:G40)-SUM(H29:H40)+SUM(J29:J40) -> 90.9
...

Sheet 1206
A1: Flat | B1: =Master!B9 -> 1206 | C1: Parking | D1: =Master!J9 -> P3-559 | E1: EWA | F1: =Master!N9 -> 1041898808 | G1: EWA limit | H1: =Master!O9 -> 20 | N1: Flat | O1: =Master!B9 -> 1206 | Q1: EWA | R1: =Master!N9 -> 1041898808
A2: Tenant | B2: =Master!C9 -> Amal | C2: Phone | D2: =Master!I9 -> 3665 2052 | E2: Lease Start | F2: =Master!K9 -> 44866 | G2: Lease end | H2: =Master!L9 -> 46326 | N2: Tenant | O2: =Master!C9 -> Amal | Q2: EWA limit | R2: =Master!O9 -> 20
A3: Month | B3: Rent | C3: EWA | D3: Chiller | E3: Internet | F3: Housekeeping | G3: Manage. fees | H3: Other fees | I3: Comments | J3: EWA Excess | K3: Excess pay | N3: Month | O3: EWA | P3: AC Chiller | R3: EWA Excess
A4: Balance: | B4: 0 | C4: Balance Date: | D4: 45291 | N4: 45778 | O4: 15.72 | P4: 15.15 | R4: =O4+P4-$R$2 -> 10.87
A5: 45292 | B5: =Master!$M$9 -> 500 | C5: 10.78 | D5: 5.25 | E5: =Master!$P$9 -> 16.18 | F5: 33 | J5: =IF((C5+D5)>$H$1,(C5+D5)-$H$1,0) -> 0 | N5: 45809 | O5: 11.76 | P5: 12.2 | R5: =O5+P5-$R$2 -> 3.96
A6: 45293 | B6: =Master!$M$9 -> 500 | C6: 10.78 | D6: 5.25 | E6: =Master!$P$9 -> 16.18 | F6: 33 | J6: =IF((C6+D6)>$H$1,(C6+D6)-$H$1,0) -> 0 | N6: 45839 | O6: 16.48 | P6: 16.65 | R6: =O6+P6-$R$2 -> 13.13
A7: 45294 | B7: =Master!$M$9 -> 500 | C7: 10.78 | D7: 5.25 | E7: =Master!$P$9 -> 16.18 | F7: 33 | J7: =IF((C7+D7)>$H$1,(C7+D7)-$H$1,0) -> 0 | N7: 45870 | O7: 17.02 | P7: 16.7 | R7: =O7+P7-$R$2 -> 13.72
A8: 45295 | B8: =Master!$M$9 -> 500 | C8: 10.78 | D8: 5.25 | E8: =Master!$P$9 -> 16.18 | F8: 33 | J8: =IF((C8+D8)>$H$1,(C8+D8)-$H$1,0) -> 0 | N8: 45901 | O8: 14.94 | P8: 8.975 | R8: =O8+P8-$R$2 -> 3.915
A9: 45296 | B9: =Master!$M$9 -> 500 | C9: 10.78 | D9: 5.25 | E9: =Master!$P$9 -> 16.18 | F9: 33 | J9: =IF((C9+D9)>$H$1,(C9+D9)-$H$1,0) -> 0 | N9: 45931 | O9: 15.98 | P9: 8.3 | R9: =O9+P9-$R$2 -> 4.28
A10: 45444 | B10: =Master!$M$9 -> 500 | C10: 14.88 | D10: 15.55 | E10: =Master!$P$9 -> 16.18 | F10: 33 | J10: =IF((C10+D10)>$H$1,(C10+D10)-$H$1,0) -> 10.43 | K10: Paid | R10: =SUM(R4:R9) -> 49.875
A11: 45474 | B11: =Master!$M$9 -> 500 | C11: 15.81 | D11: 15.65 | E11: =Master!$P$9 -> 16.18 | F11: 33 | J11: =IF((C11+D11)>$H$1,(C11+D11)-$H$1,0) -> 11.46 | K11: Paid
A12: 45505 | B12: =Master!$M$9 -> 500 | C12: 11.93 | D12: 17.5 | E12: =Master!$P$9 -> 16.18 | F12: 33 | J12: =IF((C12+D12)>$H$1,(C12+D12)-$H$1,0) -> 9.43 | K12: Paid
A13: 45536 | B13: =Master!$M$9 -> 500 | C13: 15.58 | D13: 13.475 | E13: =Master!$P$9 -> 16.18 | F13: 33 | H13: 705.408 | I13: Annual maintenance 31Aug25 | J13: =IF((C13+D13)>$H$1,(C13+D13)-$H$1,0) -> 9.055 | K13: Paid
A14: 45566 | B14: =Master!$M$9 -> 500 | C14: 13.46 | D14: 10.725 | E14: 14.5 | F14: 33 | J14: =IF((C14+D14)>$H$1,(C14+D14)-$H$1,0) -> 4.185 | K14: Paid
A15: 45597 | B15: =Master!$M$9 -> 500 | C15: =65.9-52.5 -> 13.4 | D15: 5.6 | E15: 14.5 | F15: 33 | J15: =IF((C15+D15)>$H$1,(C15+D15)-$H$1,0) -> 0
A16: 45627 | B16: =Master!$M$9 -> 500 | C16: 15.43 | D16: 1.58 | E16: 14.5 | F16: 33 | J16: =IF((C16+D16)>$H$1,(C16+D16)-$H$1,0) -> 0 | L16: =SUM(B5:B16)-SUM(C5:C16)-SUM(D5:D16)-SUM(E5:E16)-SUM(F5:F16)-SUM(G5:G16)-SUM(H5:H16)+SUM(J5:J16) -> 4493.312
A17: 45658 | B17: 500 | C17: 14.8 | D17: 0.55 | E17: 14.5 | F17: 33 | J17: =IF((C17+D17)>$H$1,(C17+D17)-$H$1,0) -> 0
A18: 45689 | B18: 500 | C18: =64.49-50.5 -> 13.99 | D18: 0.625 | E18: 14.5 | F18: 33 | J18: =IF((C18+D18)>$H$1,(C18+D18)-$H$1,0) -> 0
A19: 45717 | B19: 500 | C19: =67.27-50.5 -> 16.77 | D19: 2.225 | E19: 14.5 | F19: 33 | J19: =IF((C19+D19)>$H$1,(C19+D19)-$H$1,0) -> 0
A20: 45748 | B20: 500 | C20: =62.29-50.5 -> 11.79 | D20: 0 | E20: 14.5 | F20: 33 | J20: =IF((C20+D20)>$H$1,(C20+D20)-$H$1,0) -> 0
A21: 45778 | B21: 500 | C21: =66.22-50.5 -> 15.72 | D21: 15.15 | E21: 16.18 | F21: 33 | J21: =IF((C21+D21)>$H$1,(C21+D21)-$H$1,0) -> 10.87
A22: 45809 | B22: 500 | C22: =62.26-50.5 -> 11.76 | D22: 12.2 | E22: 16.18 | F22: 33 | J22: =IF((C22+D22)>$H$1,(C22+D22)-$H$1,0) -> 3.96
A23: 45839 | B23: 500 | C23: =66.98-50.5 -> 16.48 | D23: 16.65 | E23: 16.18 | F23: 33 | J23: =IF((C23+D23)>$H$1,(C23+D23)-$H$1,0) -> 13.13
A24: 45870 | B24: 500 | C24: =67.52-50.5 -> 17.02 | D24: 16.7 | E24: 16.18 | F24: 33 | J24: =IF((C24+D24)>$H$1,(C24+D24)-$H$1,0) -> 13.72
A25: 45901 | B25: 500 | C25: =65.44-50.5 -> 14.94 | D25: 8.975 | E25: 16.18 | F25: 33 | H25: 705.408 | I25: Annual maintenance 31Aug25 | J25: =IF((C25+D25)>$H$1,(C25+D25)-$H$1,0) -> 3.915
A26: 45931 | B26: 500 | C26: =66.48-50.5 -> 15.98 | D26: 8.3 | E26: 16.18 | F26: 33 | J26: =IF((C26+D26)>$H$1,(C26+D26)-$H$1,0) -> 4.28
A27: 45962 | B27: 500 | C27: =67.81-50.5 -> 17.31 | D27: 2.2 | E27: 16.18 | F27: 33 | J27: =IF((C27+D27)>$H$1,(C27+D27)-$H$1,0) -> 0
A28: 45992 | B28: 500 | C28: =67.5-50.5 -> 17 | D28: 1.1 | E28: 16.18 | F28: 33 | J28: =IF((C28+D28)>$H$1,(C28+D28)-$H$1,0) -> 0 | L28: =SUM(B17:B28)-SUM(C17:C28)-SUM(D17:D28)-SUM(E17:E28)-SUM(F17:F28)-SUM(G17:G28)-SUM(H17:H28)+SUM(J17:J28) -> 4492.792 | N28: =45000/12 -> 3750
A29: 46023 | J29: =IF((C29+D29)>$H$1,(C29+D29)-$H$1,0) -> 0
A30: 46054 | J30: =IF((C30+D30)>$H$1,(C30+D30)-$H$1,0) -> 0
A31: 46082 | J31: =IF((C31+D31)>$H$1,(C31+D31)-$H$1,0) -> 0
A32: 46113 | J32: =IF((C32+D32)>$H$1,(C32+D32)-$H$1,0) -> 0
A33: 46143 | J33: =IF((C33+D33)>$H$1,(C33+D33)-$H$1,0) -> 0
A34: 46174 | J34: =IF((C34+D34)>$H$1,(C34+D34)-$H$1,0) -> 0
A35: 46204 | J35: =IF((C35+D35)>$H$1,(C35+D35)-$H$1,0) -> 0
A36: 46235 | J36: =IF((C36+D36)>$H$1,(C36+D36)-$H$1,0) -> 0
A37: 46266 | J37: =IF((C37+D37)>$H$1,(C37+D37)-$H$1,0) -> 0
A38: 46296 | J38: =IF((C38+D38)>$H$1,(C38+D38)-$H$1,0) -> 0
A39: 46327 | J39: =IF((C39+D39)>$H$1,(C39+D39)-$H$1,0) -> 0
A40: 46357 | J40: =IF((C40+D40)>$H$1,(C40+D40)-$H$1,0) -> 0 | L40: =SUM(B29:B40)-SUM(C29:C40)-SUM(D29:D40)-SUM(E29:E40)-SUM(F29:F40)-SUM(G29:G40)-SUM(H29:H40)+SUM(J29:J40) -> 0
...

Sheet 1306 old
A1: Flat | B1: =Master!B10 -> 1306 | C1: Parking | D1: =Master!J10 -> P2-350 | E1: EWA | F1: =Master!N10 -> 1100872009 | G1: EWA limit | H1: =Master!O10 -> 25
A2: Tenant | B2: =Master!C10 -> Fatme Ali Hamdan | C2: Phone | D2: =Master!I10 -> 3443 8384 | E2: Lease Start | F2: =Master!K10 -> 45413 | G2: Lease end | H2: =Master!L10 -> 46142
A3: Month | B3: Rent | C3: EWA | D3: Chiller | E3: Internet | F3: Housekeeping | G3: Manage. fees | H3: Other fees | I3: Comments | J3: EWA Excess | K3: Status
A4: Balance: | B4: 0 | C4: Balance Date: | D4: 45291
A5: 45292 | B5: =Master!$M$4 -> 500 | C5: 37.47 | D5: 1.3 | E5: =Master!$P$4 -> 6 | F5: 19.8 | J5: =IF((C5+D5)>$H$1,(C5+D5)-$H$1,0) -> 13.77 | K5: Pending
A6: 45323 | B6: =Master!$M$4 -> 500 | C6: 13.12 | D6: 0.825 | E6: =Master!$P$4 -> 6 | F6: 19.8 | J6: =IF((C6+D6)>$H$1,(C6+D6)-$H$1,0) -> 0
A7: 45352 | B7: =Master!$M$4 -> 500 | C7: 8.92 | D7: 0 | E7: =Master!$P$4 -> 6 | F7: 19.8 | J7: =IF((C7+D7)>$H$1,(C7+D7)-$H$1,0) -> 0
A8: 45383 | B8: =Master!$M$4 -> 500 | C8: 5.62 | D8: 5.525 | E8: =Master!$P$4 -> 6 | F8: 19.8 | J8: =IF((C8+D8)>$H$1,(C8+D8)-$H$1,0) -> 0
A9: 45413 | B9: =Master!$M$4 -> 500 | C9: 13.12 | D9: 9.425 | E9: =Master!$P$4 -> 6 | F9: 19.8 | J9: =IF((C9+D9)>$H$1,(C9+D9)-$H$1,0) -> 0
A10: 45444 | B10: =Master!$M$4 -> 500 | C10: 11.99 | D10: 27.35 | E10: =Master!$P$4 -> 6 | F10: 19.8 | J10: =IF((C10+D10)>$H$1,(C10+D10)-$H$1,0) -> 14.34 | K10: Pending
A11: 45474 | B11: =Master!$M$4 -> 500 | C11: 14.01 | D11: 6.525 | E11: =Master!$P$4 -> 6 | F11: 19.8 | J11: =IF((C11+D11)>$H$1,(C11+D11)-$H$1,0) -> 0
A12: 45505 | B12: =Master!$M$4 -> 500 | C12: 9.01 | D12: 23.575 | E12: =Master!$P$4 -> 6 | F12: 19.8 | J12: =IF((C12+D12)>$H$1,(C12+D12)-$H$1,0) -> 7.585 | K12: Pending
A13: 45536 | B13: =Master!$M$4 -> 500 | C13: 16.07 | D13: 30.125 | E13: =Master!$P$4 -> 6 | F13: 19.8 | J13: =IF((C13+D13)>$H$1,(C13+D13)-$H$1,0) -> 21.195 | K13: Pending
A14: 45566 | B14: =Master!$M$4 -> 500 | C14: 12.45 | D14: 12.125 | E14: 14.5 | F14: 19.8 | J14: =IF((C14+D14)>$H$1,(C14+D14)-$H$1,0) -> 0
A15: 45597 | B15: =Master!$M$4 -> 500 | C15: 13.64 | D15: 5.225 | E15: 14.5 | F15: 19.8 | H15: 705.408 | I15: 1306 Annual manitenance | J15: =IF((C15+D15)>$H$1,(C15+D15)-$H$1,0) -> 0
A16: 45627 | B16: =Master!$M$4 -> 500 | C16: 8.84 | D16: 0 | E16: 14.5 | F16: 19.8 | J16: =IF((C16+D16)>$H$1,(C16+D16)-$H$1,0) -> 0 | L16: =SUM(B5:B16)-SUM(C5:C16)-SUM(D5:D16)-SUM(E5:E16)-SUM(F5:F16)-SUM(G5:G16)-SUM(H5:H16)+SUM(J5:J16) -> 4730.122
A17: 45658 | B17: 500 | C17: 6.66 | D17: 0 | E17: 14.5 | F17: 19.8 | J17: =IF((C17+D17)>$H$1,(C17+D17)-$H$1,0) -> 0
A18: 45689 | B18: 500 | C18: 12.95 | D18: 0 | E18: 14.5 | F18: 19.8 | J18: =IF((C18+D18)>$H$1,(C18+D18)-$H$1,0) -> 0
A19: 45717 | B19: 500 | C19: 11.55 | D19: 1.5 | E19: 14.5 | F19: 19.8 | J19: =IF((C19+D19)>$H$1,(C19+D19)-$H$1,0) -> 0
A20: 45748 | B20: 500 | C20: 9.1 | D20: 0 | E20: 14.5 | F20: 19.8 | J20: =IF((C20+D20)>$H$1,(C20+D20)-$H$1,0) -> 0
A21: 45778 | B21: 500 | C21: 16.53 | D21: 31.05 | E21: 14.5 | F21: 19.8 | J21: =IF((C21+D21)>$H$1,(C21+D21)-$H$1,0) -> 22.58
A22: 45809 | B22: 500 | C22: 11.18 | D22: 6.375 | E22: 14.5 | F22: 19.8 | J22: =IF((C22+D22)>$H$1,(C22+D22)-$H$1,0) -> 0
A23: 45839 | B23: 500 | C23: 11.93 | D23: 24.25 | E23: 14.5 | F23: 19.8 | J23: =IF((C23+D23)>$H$1,(C23+D23)-$H$1,0) -> 11.18
A24: 45870 | B24: 500 | C24: 15.73 | D24: 18.6 | E24: 14.5 | F24: 19.8 | H24: 55 | I24: Mixer repair | J24: =IF((C24+D24)>$H$1,(C24+D24)-$H$1,0) -> 9.33
A25: 45901 | B25: 500 | C25: 8.46 | D25: 9.05 | E25: 16.18 | F25: 19.8 | J25: =IF((C25+D25)>$H$1,(C25+D25)-$H$1,0) -> 0
A26: 45931 | B26: 500 | C26: 11.18 | D26: 8.93 | E26: 16.18 | F26: 19.8 | J26: =IF((C26+D26)>$H$1,(C26+D26)-$H$1,0) -> 0
A27: 45962 | B27: 500 | C27: 14.16 | D27: 3.225 | E27: 16.18 | F27: 19.8 | H27: 705.408 | I27: 1306 Annual manitenance | J27: =IF((C27+D27)>$H$1,(C27+D27)-$H$1,0) -> 0
A28: 45992 | B28: 500 | C28: 9.85 | D28: 0 | E28: 16.18 | F28: 19.8 | J28: =IF((C28+D28)>$H$1,(C28+D28)-$H$1,0) -> 0 | L28: =SUM(B17:B28)-SUM(C17:C28)-SUM(D17:D28)-SUM(E17:E28)-SUM(F17:F28)-SUM(G17:G28)-SUM(H17:H28)+SUM(J17:J28) -> 4622.102
B29: =SUM(B17:B28) -> 6000 | C29: =SUM(C17:C28) -> 139.28 | D29: =SUM(D17:D28) -> 102.98 | E29: =SUM(E17:E28) -> 180.72 | F29: =SUM(F17:F28) -> 237.6 | G29: =SUM(G17:G28) -> 0 | H29: =SUM(H17:H28) -> 760.408 | J29: =SUM(J5:J28) -> 99.98
A30: Net | B30: =B29-C29-D29-E29-F29-G29-H29+J29 -> 4678.992
A31: Balance: | B31: =B4+B30 -> 4678.992 | C31: Balance Date: | D31: =TODAY() -> 46029

Sheet 1306
A1: Flat | B1: =Master!B10 -> 1306 | C1: Parking | D1: =Master!J10 -> P2-350 | E1: EWA | F1: =Master!N10 -> 1100872009 | G1: EWA limit | H1: =Master!O10 -> 25
A2: Tenant | B2: =Master!C10 -> Fatme Ali Hamdan | C2: Phone | D2: =Master!I10 -> 3443 8384 | E2: Lease Start | F2: =Master!K10 -> 45413 | G2: Lease end | H2: =Master!L10 -> 46142
A3: Month | B3: Rent | C3: EWA | D3: Chiller | E3: Internet | F3: Housekeeping | G3: Manage. fees | H3: Other fees | I3: Comments | J3: EWA Excess | K3: Excess pay
A4: Balance: | B4: 0 | C4: Balance Date: | D4: 45291
A5: 45901 | B5: 500 | C5: 8.46 | D5: 9.05 | E5: 16.18 | F5: 19.8 | H5: -45 | I5: Visa for salima | J5: =IF((C5+D5)>$H$1,(C5+D5)-$H$1,0) -> 0
A6: 45931 | B6: 500 | C6: 11.18 | D6: 8.93 | E6: 16.18 | F6: 19.8 | H6: 316 | I6: Balance for ayoub | J6: =IF((C6+D6)>$H$1,(C6+D6)-$H$1,0) -> 0
A7: 45962 | B7: 500 | C7: 14.16 | D7: 3.225 | E7: 16.18 | F7: 19.8 | H7: 705.408 | I7: 1306 Annual manitenance | J7: =IF((C7+D7)>$H$1,(C7+D7)-$H$1,0) -> 0
A8: 45992 | B8: 500 | C8: 9.85 | D8: 0 | E8: 16.18 | F8: 19.8 | J8: =IF((C8+D8)>$H$1,(C8+D8)-$H$1,0) -> 0 | L8: =SUM(B5:B8)-SUM(C5:C8)-SUM(D5:D8)-SUM(E5:E8)-SUM(F5:F8)-SUM(G5:G8)-SUM(H5:H8)+SUM(J5:J8) -> 814.817
A9: 46023 | B9: 500 | E9: 16.18 | F9: 19.8 | J9: =IF((C9+D9)>$H$1,(C9+D9)-$H$1,0) -> 0
A10: 46054 | J10: =IF((C10+D10)>$H$1,(C10+D10)-$H$1,0) -> 0
A11: 46082 | J11: =IF((C11+D11)>$H$1,(C11+D11)-$H$1,0) -> 0
A12: 46113 | J12: =IF((C12+D12)>$H$1,(C12+D12)-$H$1,0) -> 0
A13: 46143 | J13: =IF((C13+D13)>$H$1,(C13+D13)-$H$1,0) -> 0
A14: 46174 | J14: =IF((C14+D14)>$H$1,(C14+D14)-$H$1,0) -> 0
A15: 46204 | J15: =IF((C15+D15)>$H$1,(C15+D15)-$H$1,0) -> 0
A16: 46235 | J16: =IF((C16+D16)>$H$1,(C16+D16)-$H$1,0) -> 0
A17: 46266 | J17: =IF((C17+D17)>$H$1,(C17+D17)-$H$1,0) -> 0
A18: 46296 | J18: =IF((C18+D18)>$H$1,(C18+D18)-$H$1,0) -> 0
A19: 46327 | J19: =IF((C19+D19)>$H$1,(C19+D19)-$H$1,0) -> 0
A20: 46357 | J20: =IF((C20+D20)>$H$1,(C20+D20)-$H$1,0) -> 0 | L20: =SUM(B9:B20)-SUM(C9:C20)-SUM(D9:D20)-SUM(E9:E20)-SUM(F9:F20)-SUM(G9:G20)-SUM(H9:H20)+SUM(J9:J20) -> 464.02
B21: =SUM(B5:B8) -> 2000 | C21: =SUM(C5:C8) -> 43.65 | D21: =SUM(D5:D8) -> 21.205 | E21: =SUM(E5:E8) -> 64.72 | F21: =SUM(F5:F8) -> 79.2 | G21: =SUM(G5:G8) -> 0 | H21: =SUM(H5:H8) -> 976.408 | J21: =SUM(J5:J8) -> 0
A22: Net | B22: =B21-C21-D21-E21-F21-G21-H21+J21 -> 814.817
A23: Balance: | B23: =B4+B22 -> 814.817 | C23: Balance Date: | D23: =TODAY() -> 46029

Sheet 1405
A1: Flat | B1: =Master!B11 -> 1405 | C1: Parking | D1: =Master!J12 -> P2-329 | E1: EWA | F1: =Master!N11 -> 1101561510 | G1: EWA limit | H1: =Master!O11 -> 25
A2: Tenant | B2: =Master!C11 -> Peter Alan | C2: Phone | D2: =Master!I11 -> 509666527 | E2: Lease Start | F2: =Master!K11 -> 45566 | G2: Lease end | H2: =Master!L11 -> 46295
A3: Month | B3: Rent | C3: EWA | D3: Chiller | E3: Internet | F3: Housekeeping | G3: Manage. fees | H3: Other fees | I3: Comments | J3: EWA Excess | K3: Excess pay
A4: Balance: | B4: 0 | C4: Balance Date: | D4: 45291
A5: 45292 | J5: =IF((D5+E5)>$H$1,(D5+E5)-$H$1,0) -> 0
A6: 45323 | J6: =IF((D6+E6)>$H$1,(D6+E6)-$H$1,0) -> 0
A7: 45352 | J7: =IF((D7+E7)>$H$1,(D7+E7)-$H$1,0) -> 0
A8: 45383 | J8: =IF((D8+E8)>$H$1,(D8+E8)-$H$1,0) -> 0
A9: 45413 | J9: =IF((D9+E9)>$H$1,(D9+E9)-$H$1,0) -> 0
A10: 45444 | J10: =IF((D10+E10)>$H$1,(D10+E10)-$H$1,0) -> 0
A11: 45474 | J11: =IF((D11+E11)>$H$1,(D11+E11)-$H$1,0) -> 0
A12: 45505 | J12: =IF((D12+E12)>$H$1,(D12+E12)-$H$1,0) -> 0
A13: 45536 | B13: 525 | I13: Security deposit | J13: =IF((D13+E13)>$H$1,(D13+E13)-$H$1,0) -> 0
A14: 45566 | B14: 372.58 | C14: 5.486 | D14: 4.705 | E14: 10.273 | F14: 23.1 | G14: 6.6 | H14: 706.464 | I14: Annual maintenance | J14: =IF((D14+E14)>$H$1,(D14+E14)-$H$1,0) -> 0
A15: 45597 | B15: =Master!$M$11*110% -> 577.5 | C15: 10.08 | D15: 0 | E15: =Master!$P$11 -> 14.5 | F15: 39.6 | H15: 52.5 | J15: =IF((D15+E15)>$H$1,(D15+E15)-$H$1,0) -> 0
A16: 45627 | B16: =Master!$M$11*110% -> 577.5 | C16: 2.26 | D16: 0 | E16: 14.5 | F16: 39.6 | H16: 52.5 | J16: =IF((D16+E16)>$H$1,(D16+E16)-$H$1,0) -> 0 | L16: =SUM(B5:B16)-SUM(C5:C16)-SUM(D5:D16)-SUM(E5:E16)-SUM(F5:F16)-SUM(G5:G16)-SUM(H5:H16)+SUM(J5:J16) -> 1070.412
A17: 45658 | B17: 577.5 | C17: 7.97 | D17: 0 | E17: 14.5 | F17: 39.6 | H17: 52.5 | J17: =IF((C17+D17)>$H$1,(C17+D17)-$H$1,0) -> 0
A18: 45689 | B18: 577.5 | C18: 15.23 | D18: 0.05 | E18: 14.5 | F18: 39.6 | H18: 52.5 | J18: =IF((C18+D18)>$H$1,(C18+D18)-$H$1,0) -> 0
A19: 45717 | B19: 577.5 | C19: 13.67 | D19: 0 | E19: 14.5 | F19: 39.6 | G19: 80 | H19: 52.5 | I19: Water heater | J19: =IF((C19+D19)>$H$1,(C19+D19)-$H$1,0) -> 0
A20: 45748 | B20: 577.5 | C20: 9.94 | D20: 0 | E20: 14.5 | F20: 39.6 | H20: 52.5 | J20: =IF((C20+D20)>$H$1,(C20+D20)-$H$1,0) -> 0
A21: 45778 | B21: 577.5 | C21: 14.92 | D21: 18.85 | E21: 16.18 | F21: 39.6 | H21: 52.5 | J21: =IF((C21+D21)>$H$1,(C21+D21)-$H$1,0) -> 8.77 | K21: Paid
A22: 45809 | B22: 577.5 | C22: 11.44 | D22: 1.375 | E22: 16.18 | F22: 39.6 | H22: 52.5 | J22: =IF((C22+D22)>$H$1,(C22+D22)-$H$1,0) -> 0
A23: 45839 | B23: 577.5 | C23: 8.32 | D23: 16.2 | E23: 16.18 | F23: 39.6 | H23: 52.5 | J23: =IF((C23+D23)>$H$1,(C23+D23)-$H$1,0) -> 0
A24: 45870 | B24: 577.5 | C24: 14.54 | D24: 26.475 | E24: 16.18 | F24: 39.6 | H24: 52.5 | J24: =IF((C24+D24)>$H$1,(C24+D24)-$H$1,0) -> 16.015 | K24: Paid
A25: 45901 | B25: 577.5 | C25: 13.38 | D25: 3.1 | E25: 16.18 | F25: 39.6 | H25: 52.5 | J25: =IF((C25+D25)>$H$1,(C25+D25)-$H$1,0) -> 0
A26: 45931 | B26: 577.5 | C26: 7.88 | D26: 8.85 | E26: 16.18 | F26: 39.6 | G26: 706.464 | H26: 52.5 | I26: Annual maintenance | J26: =IF((C26+D26)>$H$1,(C26+D26)-$H$1,0) -> 0
A27: 45962 | B27: 577.5 | C27: 14.57 | D27: 2.525 | E27: 16.18 | F27: 39.6 | H27: 52.5 | J27: =IF((C27+D27)>$H$1,(C27+D27)-$H$1,0) -> 0
A28: 45992 | B28: 577.5 | C28: 12.02 | D28: 0.05 | E28: 16.18 | F28: 39.6 | H28: 52.5 | J28: =IF((C28+D28)>$H$1,(C28+D28)-$H$1,0) -> 0 | L28: =SUM(B17:B28)-SUM(C17:C28)-SUM(D17:D28)-SUM(E17:E28)-SUM(F17:F28)-SUM(G17:G28)-SUM(H17:H28)+SUM(J17:J28) -> 4654.326
A29: 46023 | B29: 577.5 | E29: 16.18 | F29: 39.6 | H29: 52.5 | J29: =IF((C29+D29)>$H$1,(C29+D29)-$H$1,0) -> 0
A30: 46054 | J30: =IF((C30+D30)>$H$1,(C30+D30)-$H$1,0) -> 0
A31: 46082 | J31: =IF((C31+D31)>$H$1,(C31+D31)-$H$1,0) -> 0
A32: 46113 | J32: =IF((C32+D32)>$H$1,(C32+D32)-$H$1,0) -> 0
A33: 46143 | J33: =IF((C33+D33)>$H$1,(C33+D33)-$H$1,0) -> 0
A34: 46174 | J34: =IF((C34+D34)>$H$1,(C34+D34)-$H$1,0) -> 0
A35: 46204 | J35: =IF((C35+D35)>$H$1,(C35+D35)-$H$1,0) -> 0
A36: 46235 | J36: =IF((C36+D36)>$H$1,(C36+D36)-$H$1,0) -> 0
A37: 46266 | J37: =IF((C37+D37)>$H$1,(C37+D37)-$H$1,0) -> 0
A38: 46296 | J38: =IF((C38+D38)>$H$1,(C38+D38)-$H$1,0) -> 0
A39: 46327 | J39: =IF((C39+D39)>$H$1,(C39+D39)-$H$1,0) -> 0
A40: 46357 | J40: =IF((C40+D40)>$H$1,(C40+D40)-$H$1,0) -> 0 | L40: =SUM(B29:B40)-SUM(C29:C40)-SUM(D29:D40)-SUM(E29:E40)-SUM(F29:F40)-SUM(G29:G40)-SUM(H29:H40)+SUM(J29:J40) -> 469.22
...

Sheet 1706
A1: Flat | B1: =Master!B16 -> 1706 | C1: Parking | D1: =Master!J16 -> P2-385 | E1: EWA | F1: =Master!N16 -> 1101799219 | G1: EWA limit | H1: =Master!O16 -> 25
A2: Tenant | B2: =Master!C16 -> Paul | C2: Phone | D2: =Master!I16 -> 500878748 | E2: Lease Start | F2: =Master!K16 -> 45512 | G2: Lease end | H2: =Master!L16 -> 46241
A3: Month | B3: Rent | C3: EWA | D3: Chiller | E3: Internet | F3: Housekeeping | G3: Manage. fees | H3: Other fees | I3: Comments | J3: Payment to Owner | K3: EWA Excess | L3: Excess pay
A4: Balance: | B4: 0 | C4: Balance Date: | D4: 45657
A5: 45658 | B5: 222.581 | C5: 9.21 | E5: 0 | G5: 28.75 | H5: =1.7%*74000 -> 1258 | I5: Paid SLRB online
A6: 45658 | B6: 625 | E6: 0 | H6: 705.408 | I6: Annual maintenance | K6: =IF((C6+D6)>$H$1,(C6+D6)-$H$1,0) -> 0
A7: 45689 | B7: 565 | D7: 3.3 | E7: 14.484 | F7: 19.8 | G7: 28.75 | H7: 150 | I7: Title deed fees | K7: =IF((C7+D7)>$H$1,(C7+D7)-$H$1,0) -> 0
A8: 45717 | B8: 585 | D8: 4.575 | E8: 14.484 | F8: 19.8 | G8: 28.75 | K8: =IF((C8+D8)>$H$1,(C8+D8)-$H$1,0) -> 0
A9: 45748 | B9: 575 | E9: 14.484 | F9: 19.8 | G9: 28.75 | K9: =IF((C9+D9)>$H$1,(C9+D9)-$H$1,0) -> 0
A10: 45778 | B10: 575 | D10: 21.475 | E10: 14.484 | F10: 19.8 | G10: 28.75 | J10: 500 | K10: =IF((C10+D10)>$H$1,(C10+D10)-$H$1,0) -> 0
A11: 45809 | B11: 575 | D11: 6.025 | E11: 14.484 | F11: 19.8 | G11: 28.75 | J11: 500 | K11: =IF((C11+D11)>$H$1,(C11+D11)-$H$1,0) -> 0
A12: 45839 | B12: 575 | D12: 12.95 | E12: 14.484 | F12: 19.8 | G12: 28.75 | J12: 500 | K12: =IF((C12+D12)>$H$1,(C12+D12)-$H$1,0) -> 0
A13: 45870 | B13: 575 | C13: 70.13 | D13: 9.875 | E13: 14.484 | F13: 19.8 | G13: 28.75 | J13: 500 | K13: 0
A14: 45901 | B14: 575 | C14: 12.74 | D14: 11.25 | E14: 14.484 | F14: 19.8 | G14: 28.75 | J14: 500 | K14: =IF((C14+D14)>$H$1,(C14+D14)-$H$1,0) -> 0
A15: 45931 | B15: 575 | C15: 11.27 | D15: 11.28 | E15: 14.484 | F15: 19.8 | G15: 28.75 | H15: 1200 | I15: CPR fees | K15: =IF((C15+D15)>$H$1,(C15+D15)-$H$1,0) -> 0
A16: 45962 | B16: 575 | C16: 16.27 | D16: 9.05 | E16: 14.484 | F16: 19.8 | G16: 28.75 | K16: 0
A17: 45992 | B17: 575 | C17: 14.59 | D17: 3.625 | E17: 14.484 | F17: 19.8 | G17: 28.75 | K17: =IF((C17+D17)>$H$1,(C17+D17)-$H$1,0) -> 0
B18: =SUM(B5:B17) -> 7172.581 | C18: =SUM(C5:C17) -> 134.21 | D18: =SUM(D5:D17) -> 93.405 | E18: =SUM(E5:E17) -> 159.324 | F18: =SUM(F5:F17) -> 217.8 | G18: =SUM(G5:G17) -> 345 | H18: =SUM(H5:H17) -> 3313.408 | J18: =SUM(J5:J17) -> 2500 | K18: =SUM(K5:K17) -> 0 | M18: =SUM(B5:B17)-SUM(C5:C17)-SUM(D5:D17)-SUM(E5:E17)-SUM(F5:F17)-SUM(G5:G17)-SUM(H5:H17)-SUM(J5:J17)+SUM(K5:K17) -> 409.434
A19: Net | B19: =B18-C18-D18-E18-F18-G18-H18-J18+K18 -> 409.434
A20: Balance: | B20: =B4+B19 -> 409.434 | C20: Balance Date: | D20: 46022
A21: 45658 | B21: 575 | E21: 14.484 | F21: 19.8 | G21: 28.75 | K21: =IF((C21+D21)>$H$1,(C21+D21)-$H$1,0) -> 0
